<?xml version="1.0" ?>
<!-- =================================================================================== -->
<!-- |    This document was autogenerated by xacro from combined.xacro                 | -->
<!-- |    EDITING THIS FILE BY HAND IS NOT RECOMMENDED                                 | -->
<!-- =================================================================================== -->
<robot name="combined">
  <material name="slategray0">
    <color rgba="0.4375 0.50 0.5625 1.0"/>
  </material>
  <material name="slategray1">
    <color rgba="0.5375 0.60 0.6625 1.0"/>
  </material>
  <material name="white">
    <color rgba="1 1 1 1.0"/>
  </material>
  <link name="jig_base_link">
    <visual>
      <origin rpy="0 0 -1.5707963267948966" xyz="3.9000999999999997 0.0 0.001"/>
      <geometry>
        <box size="5.01 9.03  0.002"/>
      </geometry>
      <material name="">
        <color rgba="0.4375 0.50 0.5625 1.0"/>
      </material>
    </visual>
    <collision>
      <origin rpy="0 0 -1.5707963267948966" xyz="3.9000999999999997 0.0 0.001"/>
      <geometry>
        <box size="5.01 9.03  0.002"/>
      </geometry>
    </collision>
  </link>
  <link name="jig_link_1">
    <visual>
      <origin rpy="0 0 -1.5707963267948966" xyz="0 0 0"/>
      <geometry>
        <mesh filename="meshes\visual\jig\link_1_visual.stl"/>
      </geometry>
      <material name="">
        <color rgba="0.4375 0.50 0.5625 1.0"/>
      </material>
    </visual>
    <collision>
      <origin rpy="0 0 -1.5707963267948966" xyz="0 0 0"/>
      <geometry>
        <mesh filename="meshes\collision\jig\link_1_collision.stl"/>
      </geometry>
    </collision>
    <inertial>
      <origin rpy="0 0 0" xyz="0 0 0"/>
      <mass value="1000"/>
      <inertia ixx="100000" ixy="0" ixz="0" iyy="100000" iyz="0" izz="100000"/>
    </inertial>
  </link>
  <!-- JOINTS -->
  <joint name="jig_base_link_to_jig_link_1" type="fixed">
    <origin rpy="0.0 0.0 0.0" xyz="0.0 0.0 0.002"/>
    <parent link="jig_base_link"/>
    <child link="jig_link_1"/>
  </joint>
  <!-- Add URDF transmission elements (for ros_control) -->
  <!-- <xacro:ur_arm_transmission prefix="${prefix}" hw_interface="${transmission_hw_interface}" /> -->
  <!-- LINKS -->
  <link name="gantry_base_link">
    <visual>
      <origin rpy="0 0 0" xyz="0 0 0"/>
      <geometry>
        <mesh filename="meshes\visual\gantry_base_link_right.dae"/>
      </geometry>
    </visual>
    <collision>
      <origin rpy="0 0 0" xyz="0 0 0"/>
      <geometry>
        <mesh filename="meshes\collision\gantry_base_link_right.stl"/>
      </geometry>
    </collision>
    <inertial>
      <origin rpy="0 0 0" xyz="6.65 5.51 1.12"/>
      <mass value="5307.83"/>
      <inertia ixx="304820.65" ixy="-194531.63" ixz="39408.49" iyy="354714.68" iyz="-32769.00" izz="613717.85"/>
    </inertial>
  </link>
  <link name="gantry_base_link_left">
    <visual>
      <origin rpy="0 0 0" xyz="0 0 0"/>
      <geometry>
        <mesh filename="meshes\visual\gantry_base_link_left.dae"/>
      </geometry>
    </visual>
    <collision>
      <origin rpy="0 0 0" xyz="0 0 0"/>
      <geometry>
        <mesh filename="meshes\collision\gantry_base_link_left.stl"/>
      </geometry>
    </collision>
    <inertial>
      <origin rpy="0 0 0" xyz="6.65 5.51 1.12"/>
      <mass value="5307.83"/>
      <inertia ixx="304820.65" ixy="-194531.63" ixz="39408.49" iyy="354714.68" iyz="-32769.00" izz="613717.85"/>
    </inertial>
  </link>
  <joint name="gantry_base_link_joint" type="fixed">
    <parent link="gantry_base_link"/>
    <child link="gantry_base_link_left"/>
    <origin rpy="0 0 0" xyz="0 9.52 0"/>
  </joint>
  <link name="gantry_link_1">
    <visual>
      <origin rpy="0 0 0" xyz="0 0 0"/>
      <geometry>
        <mesh filename="meshes\visual\link_1.dae"/>
      </geometry>
    </visual>
    <collision>
      <origin rpy="0 0 0" xyz="0 0 0"/>
      <geometry>
        <mesh filename="meshes\collision\link_1.stl"/>
      </geometry>
    </collision>
    <inertial>
      <origin rpy="0 0 0" xyz="-0.36 4.40 0.0"/>
      <mass value="615.22"/>
      <inertia ixx="19382.63" ixy="-977.55" ixz="-3.51" iyy="278.07" iyz="6.57" izz="19578.31"/>
    </inertial>
  </link>
  <link name="gantry_link_2">
    <visual>
      <origin rpy="0 0 0" xyz="0 0 0"/>
      <geometry>
        <mesh filename="meshes\visual\link_2.dae"/>
      </geometry>
    </visual>
    <collision>
      <origin rpy="0 0 0" xyz="0 0 0"/>
      <geometry>
        <mesh filename="meshes\collision\link_2.stl"/>
      </geometry>
    </collision>
    <inertial>
      <origin rpy="0 0 0" xyz="0.05 -0.37 0.04"/>
      <mass value="76.4"/>
      <inertia ixx="33.00" ixy="-2.28" ixz="0.28" iyy="8.08" iyz="-1.96" izz="26.56"/>
    </inertial>
  </link>
  <link name="gantry_link_3">
    <visual>
      <origin rpy="0 0 0" xyz="0 0 0"/>
      <geometry>
        <mesh filename="meshes\visual\link_3.dae"/>
      </geometry>
    </visual>
    <collision>
      <origin rpy="0 0 0" xyz="0 0 0"/>
      <geometry>
        <mesh filename="meshes\collision\link_3.stl"/>
      </geometry>
    </collision>
    <inertial>
      <origin rpy="0 0 0" xyz="0.19 0 0.78"/>
      <mass value="65.36"/>
      <inertia ixx="75.70" ixy="0.00" ixz="9.18" iyy="75.41" iyz="-0.06" izz="8.24"/>
    </inertial>
  </link>
  <link name="gantry_link_4">
    <visual>
      <origin rpy="0 0 0" xyz="0 0 0"/>
      <geometry>
        <mesh filename="meshes\visual\link_4.dae"/>
      </geometry>
    </visual>
    <collision>
      <origin rpy="0 0 0" xyz="0 0 0"/>
      <geometry>
        <mesh filename="meshes\collision\link_4.stl"/>
      </geometry>
    </collision>
    <inertial>
      <origin rpy="0 0 0" xyz="0.01 -0.03 1.18"/>
      <mass value="41.91"/>
      <inertia ixx="83.04" ixy="-0.18" ixz="-0.82" iyy="82.65" iyz="2.19" izz="1.32"/>
    </inertial>
  </link>
  <link name="gantry_link_5">
    <visual>
      <origin rpy="0 0 0" xyz="0 0 0"/>
      <geometry>
        <mesh filename="meshes\visual\link_5.dae"/>
      </geometry>
    </visual>
    <collision>
      <origin rpy="0 0 0" xyz="0 0 0"/>
      <geometry>
        <mesh filename="meshes\collision\link_5.stl"/>
      </geometry>
    </collision>
    <inertial>
      <origin rpy="0 0 0" xyz="9.24 7.36 4.82"/>
      <mass value="4"/>
      <inertia ixx="17" ixy="0" ixz="0" iyy="17" iyz="0" izz="17"/>
    </inertial>
  </link>
  <!-- Following REP199, the designation "flange" frame is used to attach the EEF -->
  <link name="gantry_flange"/>
  <!-- Again following REP199, "base" and "tool0" frames are equivalend to the coordinate frame defined in KUKA KRC controllers for the $ROBROOT and $TOOL -->
  <link name="gantry_base"/>
  <link name="gantry_tool0"/>
  <!-- JOINTS -->
  <joint name="gantry_joint_1" type="prismatic">
    <parent link="gantry_base_link"/>
    <child link="gantry_link_1"/>
    <origin rpy="0 0 0" xyz="2.3064761 0.76 4.709"/>
    <axis xyz="1 0 0"/>
    <limit effort="0.0" lower="-0.01" upper="9.01" velocity="2.0"/>
  </joint>
  <joint name="gantry_joint_2" type="prismatic">
    <parent link="gantry_link_1"/>
    <child link="gantry_link_2"/>
    <origin rpy="0 0 0.0020804324683772408" xyz="0 1.0931799 0"/>
    <axis xyz="0 1 0"/>
    <!-- <axis xyz="-0.002081 0.999997 0"/> -->
    <limit effort="0.0" lower="-0.01" upper="7.15" velocity="2.0"/>
  </joint>
  <joint name="gantry_joint_3" type="prismatic">
    <parent link="gantry_link_2"/>
    <child link="gantry_link_3"/>
    <origin rpy="0 0 0" xyz="0.2865 0 -0.2184263"/>
    <axis xyz="0 0 1"/>
    <limit effort="0.0" lower="-0.77" upper="0.01" velocity="0.5"/>
  </joint>
  <joint name="gantry_joint_4" type="prismatic">
    <parent link="gantry_link_3"/>
    <child link="gantry_link_4"/>
    <origin rpy="0 0 0" xyz="0 0 -0.598"/>
    <axis xyz="0 0 1"/>
    <limit effort="0.0" lower="-1.16" upper="0.01" velocity="0.5"/>
  </joint>
  <joint name="gantry_joint_5" type="revolute">
    <parent link="gantry_link_4"/>
    <child link="gantry_link_5"/>
    <origin rpy="0 0 0" xyz="0 0 -0.1839"/>
    <axis xyz="0 0 1"/>
    <limit effort="0.0" lower="-6.283185307179586" upper="6.283185307179586" velocity="0.5235987755982988"/>
  </joint>
  <joint name="gantry_joint_5_to_gantry_flange" type="fixed">
    <parent link="gantry_link_5"/>
    <child link="gantry_flange"/>
    <origin rpy="0 1.5707963267948966 0" xyz="0 0 0"/>
  </joint>
  <!-- Modify according to the $ROBROOT and $TOOL specified in the robot controller -->
  <joint name="gantry_base_link_to_gantry_base" type="fixed">
    <parent link="gantry_base_link"/>
    <child link="gantry_base"/>
    <origin rpy="0 0 0" xyz="0 0 0"/>
  </joint>
  <joint name="gantry_flange_to_gantry_tool0" type="fixed">
    <parent link="gantry_flange"/>
    <child link="gantry_tool0"/>
    <origin rpy="0 -1.5707963267948966 0" xyz="0 0 0"/>
  </joint>
  <!-- LIMIT FRAMES -->
  <!-- x Limits -->
  <link name="gantry_joint_1_lower_physical_limit"/>
  <link name="gantry_joint_1_lower_hard_limit"/>
  <link name="gantry_joint_1_lower_soft_limit"/>
  <link name="gantry_joint_1_null_point"/>
  <link name="gantry_joint_1_upper_physical_limit"/>
  <link name="gantry_joint_1_upper_hard_limit"/>
  <link name="gantry_joint_1_upper_soft_limit"/>
  <link name="gantry_joint_1_end_point"/>
  <joint name="gantry_base_link_to_gantry_joint_1_lower_physical_limit" type="fixed">
    <parent link="gantry_base_link"/>
    <child link="gantry_joint_1_lower_physical_limit"/>
    <origin rpy="0 0 0" xyz="0.248 0.425 4.903"/>
  </joint>
  <joint name="gantry_joint_1_lower_physical_limit_to_gantry_joint_1_lower_hard_limit" type="fixed">
    <parent link="gantry_joint_1_lower_physical_limit"/>
    <child link="gantry_joint_1_lower_hard_limit"/>
    <origin rpy="0 0 0" xyz="0.158 0 0"/>
  </joint>
  <joint name="gantry_joint_1_lower_hard_limit_to_gantry_joint_1_lower_soft_limit" type="fixed">
    <parent link="gantry_joint_1_lower_hard_limit"/>
    <child link="gantry_joint_1_lower_soft_limit"/>
    <origin rpy="0 0 0" xyz="0.025 0 0"/>
  </joint>
  <joint name="gantry_joint_1_lower_soft_limit_to_gantry_joint_1_null_point" type="fixed">
    <parent link="gantry_joint_1_lower_soft_limit"/>
    <child link="gantry_joint_1_null_point"/>
    <origin rpy="0 0 0" xyz="0.01 0 0"/>
  </joint>
  <joint name="gantry_base_link_to_gantry_joint_1_upper_physical_limit" type="fixed">
    <parent link="gantry_base_link"/>
    <child link="gantry_joint_1_upper_physical_limit"/>
    <origin rpy="0 0 0" xyz="12.245 0.425 4.903"/>
  </joint>
  <joint name="gantry_joint_1_upper_physical_limit_to_gantry_joint_1_upper_hard_limit" type="fixed">
    <parent link="gantry_joint_1_upper_physical_limit"/>
    <child link="gantry_joint_1_upper_hard_limit"/>
    <origin rpy="0 0 0" xyz="-0.186 0 0"/>
  </joint>
  <joint name="gantry_joint_1_upper_hard_limit_to_gantry_joint_1_upper_soft_limit" type="fixed">
    <parent link="gantry_joint_1_upper_hard_limit"/>
    <child link="gantry_joint_1_upper_soft_limit"/>
    <origin rpy="0 0 0" xyz="-0.058 0 0"/>
  </joint>
  <joint name="gantry_joint_1_upper_soft_limit_to_gantry_joint_1_end_point" type="fixed">
    <parent link="gantry_joint_1_upper_soft_limit"/>
    <child link="gantry_joint_1_end_point"/>
    <origin rpy="0 0 0" xyz="-0.01 0 0"/>
  </joint>
  <!-- Y Limits -->
  <link name="gantry_joint_2_lower_physical_limit"/>
  <link name="gantry_joint_2_lower_hard_limit"/>
  <link name="gantry_joint_2_lower_soft_limit"/>
  <link name="gantry_joint_2_null_point"/>
  <link name="gantry_joint_2_upper_physical_limit"/>
  <link name="gantry_joint_2_upper_hard_limit"/>
  <link name="gantry_joint_2_upper_soft_limit"/>
  <link name="gantry_joint_2_end_point"/>
  <joint name="gantry_link_1_to_gantry_joint_2_lower_physical_limit" type="fixed">
    <parent link="gantry_link_1"/>
    <child link="gantry_joint_2_lower_physical_limit"/>
    <origin rpy="0 0 0" xyz="0.086 0.032 0.06125"/>
  </joint>
  <joint name="gantry_joint_2_lower_physical_limit_to_gantry_joint_2_lower_hard_limit" type="fixed">
    <parent link="gantry_joint_2_lower_physical_limit"/>
    <child link="gantry_joint_2_lower_hard_limit"/>
    <origin rpy="0 0 0" xyz="0 0.056 0"/>
  </joint>
  <joint name="gantry_joint_2_lower_hard_limit_to_gantry_joint_2_lower_soft_limit" type="fixed">
    <parent link="gantry_joint_2_lower_hard_limit"/>
    <child link="gantry_joint_2_lower_soft_limit"/>
    <origin rpy="0 0 0" xyz="0 0.025 0"/>
  </joint>
  <joint name="gantry_joint_2_lower_soft_limit_to_gantry_joint_2_null_point" type="fixed">
    <parent link="gantry_joint_2_lower_soft_limit"/>
    <child link="gantry_joint_2_null_point"/>
    <origin rpy="0 0 0" xyz="0 0.01 0"/>
  </joint>
  <joint name="gantry_link_1_to_gantry_joint_2_upper_physical_limit" type="fixed">
    <parent link="gantry_link_1"/>
    <child link="gantry_joint_2_upper_physical_limit"/>
    <origin rpy="0 0 0" xyz="0.086 8.818 0.06125"/>
  </joint>
  <joint name="gantry_joint_2_upper_physical_limit_to_gantry_joint_2_upper_hard_limit" type="fixed">
    <parent link="gantry_joint_2_upper_physical_limit"/>
    <child link="gantry_joint_2_upper_hard_limit"/>
    <origin rpy="0 0 0" xyz="0 -0.025 0"/>
  </joint>
  <joint name="gantry_joint_2_upper_hard_limit_to_gantry_joint_2_upper_soft_limit" type="fixed">
    <parent link="gantry_joint_2_upper_hard_limit"/>
    <child link="gantry_joint_2_upper_soft_limit"/>
    <origin rpy="0 0 0" xyz="0 -0.025 0"/>
  </joint>
  <joint name="gantry_joint_2_upper_soft_limit_to_gantry_joint_2_end_point" type="fixed">
    <parent link="gantry_joint_2_upper_soft_limit"/>
    <child link="gantry_joint_2_end_point"/>
    <origin rpy="0 0 0" xyz="0 -0.01 0"/>
  </joint>
  <!-- Z1 Limits -->
  <link name="gantry_joint_3_lower_physical_limit"/>
  <link name="gantry_joint_3_lower_hard_limit"/>
  <link name="gantry_joint_3_lower_soft_limit"/>
  <link name="gantry_joint_3_null_point"/>
  <link name="gantry_joint_3_upper_physical_limit"/>
  <link name="gantry_joint_3_upper_hard_limit"/>
  <link name="gantry_joint_3_upper_soft_limit"/>
  <link name="gantry_joint_3_end_point"/>
  <joint name="gantry_link_2_to_gantry_joint_3_upper_physical_limit" type="fixed">
    <parent link="gantry_link_2"/>
    <child link="gantry_joint_3_upper_physical_limit"/>
    <origin rpy="0 0 0" xyz="0.22649999999999998 0.4125 -0.28"/>
  </joint>
  <joint name="gantry_joint_3_upper_physical_limit_to_gantry_joint_3_upper_hard_limit" type="fixed">
    <parent link="gantry_joint_3_upper_physical_limit"/>
    <child link="gantry_joint_3_upper_hard_limit"/>
    <origin rpy="0 0 0" xyz="0 0 -0.194"/>
  </joint>
  <joint name="gantry_joint_3_upper_hard_limit_to_gantry_joint_3_upper_soft_limit" type="fixed">
    <parent link="gantry_joint_3_upper_hard_limit"/>
    <child link="gantry_joint_3_upper_soft_limit"/>
    <origin rpy="0 0 0" xyz="0 0 -0.025"/>
  </joint>
  <joint name="gantry_joint_3_upper_soft_limit_to_gantry_joint_3_null_point" type="fixed">
    <parent link="gantry_joint_3_upper_soft_limit"/>
    <child link="gantry_joint_3_null_point"/>
    <origin rpy="0 0 0" xyz="0 0 -0.01"/>
  </joint>
  <joint name="gantry_link_2_to_gantry_joint_3_lower_physical_limit" type="fixed">
    <parent link="gantry_link_2"/>
    <child link="gantry_joint_3_lower_physical_limit"/>
    <origin rpy="0 0 0" xyz="0.22649999999999998 0.4125 0.18"/>
  </joint>
  <joint name="gantry_joint_3_lower_physical_limit_to_gantry_joint_3_lower_hard_limit" type="fixed">
    <parent link="gantry_joint_3_lower_physical_limit"/>
    <child link="gantry_joint_3_lower_hard_limit"/>
    <origin rpy="0 0 0" xyz="0 0 0.026"/>
  </joint>
  <joint name="gantry_joint_3_lower_hard_limit_to_gantry_joint_3_lower_soft_limit" type="fixed">
    <parent link="gantry_joint_3_lower_hard_limit"/>
    <child link="gantry_joint_3_lower_soft_limit"/>
    <origin rpy="0 0 0" xyz="0 0 0.005"/>
  </joint>
  <joint name="gantry_joint_3_lower_soft_limit_to_gantry_joint_3_end_point" type="fixed">
    <parent link="gantry_joint_3_lower_soft_limit"/>
    <child link="gantry_joint_3_end_point"/>
    <origin rpy="0 0 0" xyz="0 0 0.01"/>
  </joint>
  <!-- Z2 Limits -->
  <link name="gantry_joint_4_lower_physical_limit"/>
  <link name="gantry_joint_4_lower_hard_limit"/>
  <link name="gantry_joint_4_lower_soft_limit"/>
  <link name="gantry_joint_4_null_point"/>
  <link name="gantry_joint_4_upper_physical_limit"/>
  <link name="gantry_joint_4_upper_hard_limit"/>
  <link name="gantry_joint_4_upper_soft_limit"/>
  <link name="gantry_joint_4_end_point"/>
  <joint name="gantry_link_3_to_gantry_joint_4_upper_physical_limit" type="fixed">
    <parent link="gantry_link_3"/>
    <child link="gantry_joint_4_upper_physical_limit"/>
    <origin rpy="0 0 0" xyz="0.167 0 -0.5415"/>
  </joint>
  <joint name="gantry_joint_4_upper_physical_limit_to_gantry_joint_4_upper_hard_limit" type="fixed">
    <parent link="gantry_joint_4_upper_physical_limit"/>
    <child link="gantry_joint_4_upper_hard_limit"/>
    <origin rpy="0 0 0" xyz="0 0 -0.04"/>
  </joint>
  <joint name="gantry_joint_4_upper_hard_limit_to_gantry_joint_4_upper_soft_limit" type="fixed">
    <parent link="gantry_joint_4_upper_hard_limit"/>
    <child link="gantry_joint_4_upper_soft_limit"/>
    <origin rpy="0 0 0" xyz="0 0 -0.025"/>
  </joint>
  <joint name="gantry_joint_4_upper_soft_limit_to_gantry_joint_4_null_point" type="fixed">
    <parent link="gantry_joint_4_upper_soft_limit"/>
    <child link="gantry_joint_4_null_point"/>
    <origin rpy="0 0 0" xyz="0 0 -0.01"/>
  </joint>
  <joint name="gantry_link_3_to_gantry_joint_4_lower_physical_limit" type="fixed">
    <parent link="gantry_link_3"/>
    <child link="gantry_joint_4_lower_physical_limit"/>
    <origin rpy="0 0 0" xyz="0.167 0 -0.5065"/>
  </joint>
  <joint name="gantry_joint_4_lower_physical_limit_to_gantry_joint_4_lower_hard_limit" type="fixed">
    <parent link="gantry_joint_4_lower_physical_limit"/>
    <child link="gantry_joint_4_lower_hard_limit"/>
    <origin rpy="0 0 0" xyz="0 0 0.03"/>
  </joint>
  <joint name="gantry_joint_4_lower_hard_limit_to_gantry_joint_4_lower_soft_limit" type="fixed">
    <parent link="gantry_joint_4_lower_hard_limit"/>
    <child link="gantry_joint_4_lower_soft_limit"/>
    <origin rpy="0 0 0" xyz="0 0 0.005"/>
  </joint>
  <joint name="gantry_joint_4_lower_soft_limit_to_gantry_joint_4_end_point" type="fixed">
    <parent link="gantry_joint_4_lower_soft_limit"/>
    <child link="gantry_joint_4_end_point"/>
    <origin rpy="0 0 0" xyz="0 0 0.01"/>
  </joint>
  <!-- CALIBRATION FRAMES -->
  <link name="gantry_calibration_frame"/>
  <link name="gantry_reflector_frame"/>
  <joint name="gantry_base_link_to_gantry_calibration_frame" type="fixed">
    <parent link="gantry_base_link"/>
    <child link="gantry_calibration_frame"/>
    <origin rpy="0 0 0" xyz="0.6003999999999999 0.5655 0.40532"/>
    <!-- <origin xyz="0.6004 0.5655 0.40532" rpy="0 0 0"/> -->
  </joint>
  <joint name="gantry_flange_to_gantry_reflector_frame" type="fixed">
    <parent link="gantry_flange"/>
    <child link="gantry_reflector_frame"/>
    <!-- <origin xyz="${-0.0179+drift_nest_offset} ${0.1592-drift_nest_radius} ${0.5546-drift_nest_radius}" rpy="0 -${pi*0.5} 0"/> -->
    <origin rpy="0 -1.5707963267948966 0" xyz="0.011530499999999999 0.1405472 0.5365482"/>
  </joint>
  <!-- Add URDF transmission elements (for ros_control) -->
  <!-- <xacro:ur_arm_transmission prefix="${prefix}" hw_interface="${transmission_hw_interface}" /> -->
  <!-- LINKS -->
  <link name="wrist_base_link">
    <visual>
      <origin rpy="0 0 0" xyz="0 0 0"/>
      <geometry>
        <mesh filename="meshes\visual\wrist_base_link.dae"/>
      </geometry>
      <material name="slategray0"/>
    </visual>
    <collision>
      <origin rpy="0 0 0" xyz="0 0 0"/>
      <geometry>
        <mesh filename="meshes\collision\wrist_base_link.stl"/>
      </geometry>
    </collision>
    <inertial>
      <mass value="16"/>
      <inertia ixx="0" ixy="0" ixz="0" iyy="2" iyz="0" izz="1"/>
    </inertial>
  </link>
  <link name="wrist_link_1">
    <visual>
      <origin rpy="0 0 0" xyz="0 0 0"/>
      <geometry>
        <mesh filename="meshes\visual\wrist_link_1.dae"/>
      </geometry>
      <material name="slategray0"/>
    </visual>
    <collision>
      <origin rpy="0 0 0" xyz="0 0 0"/>
      <geometry>
        <mesh filename="meshes\collision\wrist_link_1.stl"/>
      </geometry>
    </collision>
    <inertial>
      <mass value="11"/>
      <inertia ixx="1" ixy="0" ixz="0" iyy="1" iyz="0" izz="1"/>
    </inertial>
  </link>
  <link name="wrist_link_2">
    <visual>
      <origin rpy="0 0 0" xyz="0 0 0"/>
      <geometry>
        <mesh filename="meshes\visual\wrist_link_2.dae"/>
      </geometry>
    </visual>
    <collision>
      <origin rpy="0 0 0" xyz="0 0 0"/>
      <geometry>
        <mesh filename="meshes\collision\wrist_link_2.stl"/>
      </geometry>
    </collision>
    <inertial>
      <mass value="2.34"/>
      <inertia ixx="0.45" ixy="0" ixz="0" iyy="0.45" iyz="-0.01" izz="0.02"/>
    </inertial>
  </link>
  <link name="wrist_flange"/>
  <link name="wrist_tool0"/>
  <!-- JOINTS -->
  <joint name="wrist_joint_6" type="revolute">
    <parent link="wrist_base_link"/>
    <child link="wrist_link_1"/>
    <origin rpy="0 0 0" xyz="0.221 0 0"/>
    <axis xyz="0 -1 0"/>
    <limit effort="0.0" lower="-1.6580627893946132" upper="1.6580627893946132" velocity="0.3141592653589793"/>
  </joint>
  <joint name="wrist_joint_7" type="revolute">
    <parent link="wrist_link_1"/>
    <child link="wrist_link_2"/>
    <origin rpy="0 0 0" xyz="0.268 0 0"/>
    <axis xyz="1 0 0"/>
    <limit effort="0.0" lower="-3.141592653589793" upper="3.141592653589793" velocity="314.1592653589793"/>
  </joint>
  <joint name="wrist_link_2_to_wrist_flange" type="fixed">
    <parent link="wrist_link_2"/>
    <child link="wrist_flange"/>
    <origin rpy="0 0 0" xyz="0 0 0"/>
  </joint>
  <joint name="wrist_flange_to_wrist_tool0" type="fixed">
    <parent link="wrist_flange"/>
    <child link="wrist_tool0"/>
    <origin rpy="0 -1.5707963267948966 0" xyz="0 0 0"/>
  </joint>
  <joint name="gantry_flange_to_wrist_base_link" type="fixed">
    <parent link="gantry_flange"/>
    <child link="wrist_base_link"/>
    <origin rpy="0 0 0" xyz="0 0 0.0"/>
  </joint>
  <link name="quickrelease_base_link">
    <visual>
      <origin rpy="0 0 0" xyz="0 0 0"/>
      <geometry>
        <mesh filename="meshes\visual\quickrelease_connector.dae"/>
      </geometry>
    </visual>
    <collision>
      <origin rpy="0 0 0" xyz="0 0 0"/>
      <geometry>
        <mesh filename="meshes\collision\quickrelease_connector.stl"/>
      </geometry>
    </collision>
  </link>
  <link name="quickrelease_link_1">
    <visual>
      <origin rpy="0 0 0" xyz="0 0 0"/>
      <geometry>
        <mesh filename="meshes\visual\quickrelease_g_sws250_2o.dae"/>
      </geometry>
    </visual>
    <collision>
      <origin rpy="0 0 0" xyz="0 0 0"/>
      <geometry>
        <mesh filename="meshes\collision\quickrelease_g_sws250_2o.stl"/>
      </geometry>
    </collision>
  </link>
  <link name="quickrelease_link_2">
    <visual>
      <origin rpy="0 0 0" xyz="0 0 0"/>
      <geometry>
        <mesh filename="meshes\visual\quickrelease_g_sws250_2u.dae"/>
      </geometry>
    </visual>
    <collision>
      <origin rpy="0 0 0" xyz="0 0 0"/>
      <geometry>
        <mesh filename="meshes\collision\quickrelease_g_sws250_2u.stl"/>
      </geometry>
    </collision>
  </link>
  <link name="quickrelease_flange"/>
  <!-- JOINTS -->
  <joint name="quickrelease_base_link_to_quickrelease_link_1" type="fixed">
    <parent link="quickrelease_base_link"/>
    <child link="quickrelease_link_1"/>
    <origin rpy="0 0 0 " xyz="0.026 0 0"/>
  </joint>
  <joint name="quickrelease_link_1_to_quickrelease_link_2" type="fixed">
    <origin rpy="0.0 0.0 0.0" xyz="0.078 0.0 0.0"/>
    <parent link="quickrelease_link_1"/>
    <child link="quickrelease_link_2"/>
  </joint>
  <joint name="quickrelease_link_2_to_quickrelease_flange" type="fixed">
    <origin rpy="0.0 0.0 0.0" xyz="0.026 0.0 0.0"/>
    <parent link="quickrelease_link_2"/>
    <child link="quickrelease_flange"/>
  </joint>
  <!-- JOINTS -->
  <joint name="wrist_flange_to_quickrelease_base_link" type="fixed">
    <parent link="wrist_flange"/>
    <child link="quickrelease_base_link"/>
    <origin rpy="1.5707963267948966 0 0" xyz="0 0 0 "/>
  </joint>
  <!-- WALLS -->
  <link name="walls">
    <collision>
      <!-- Back Wall  -->
      <origin rpy="0 0 0" xyz="-0.005 5.185 3.25"/>
      <geometry>
        <box size="0.01 10.37 6.5"/>
      </geometry>
    </collision>
    <collision>
      <!-- Front Wall  -->
      <origin rpy="0 0 0" xyz="13.665 5.185 3.25"/>
      <geometry>
        <box size="0.01 10.37 6.5"/>
      </geometry>
    </collision>
    <collision>
      <!-- Floor Wall  -->
      <origin rpy="0 1.5707963267948966 0" xyz="6.835 5.185 -0.005"/>
      <geometry>
        <box size="0.01 10.37 13.67"/>
      </geometry>
    </collision>
    <collision>
      <!-- Ceiling Wall -->
      <origin rpy="0 1.5707963267948966 0" xyz="6.835 5.185 6.495"/>
      <geometry>
        <box size="0.01 10.37 13.67"/>
      </geometry>
    </collision>
  </link>
  <joint name="gantry_base_link_to_walls" type="fixed">
    <parent link="gantry_base_link"/>
    <child link="walls"/>
    <origin rpy="0 0 0" xyz="0 0 0"/>
  </joint>
  <joint name="camera_y_axis_right_joint" type="fixed">
    <parent link="gantry_link_1"/>
    <child link="camera_y_axis_right_link"/>
    <origin rpy="0 1.1344640137963142 1.5707963267948966" xyz="-0.4 0.05 -0.5"/>
  </joint>
  <link name="camera_y_axis_right_link">
    <visual>
      <geometry>
        <box size="0.085 0.049 0.049"/>
      </geometry>
      <material name="green">
        <color rgba="0 1 0 1"/>
      </material>
    </visual>
  </link>
  <joint name="camera_y_axis_right_optical_joint" type="fixed">
    <parent link="camera_y_axis_right_link"/>
    <child link="camera_y_axis_right_optical_frame"/>
    <origin rpy="-1.5707963267948966 0 -1.5707963267948966" xyz="0 0 0"/>
  </joint>
  <link name="camera_y_axis_right_optical_frame"/>
  <joint name="camera_y_axis_left_joint" type="fixed">
    <parent link="gantry_link_1"/>
    <child link="camera_y_axis_left_link"/>
    <origin rpy="0 1.1344640137963142 -1.5707963267948966" xyz="-0.4 8.8 -0.5"/>
  </joint>
  <link name="camera_y_axis_left_link">
    <visual>
      <geometry>
        <box size="0.085 0.049 0.049"/>
      </geometry>
      <material name="green">
        <color rgba="0 1 0 1"/>
      </material>
    </visual>
  </link>
  <joint name="camera_y_axis_left_optical_joint" type="fixed">
    <parent link="camera_y_axis_left_link"/>
    <child link="camera_y_axis_left_optical_frame"/>
    <origin rpy="-1.5707963267948966 0 -1.5707963267948966" xyz="0 0 0"/>
  </joint>
  <link name="camera_y_axis_left_optical_frame"/>
  <joint name="camera_rear_left_corner_joint" type="fixed">
    <parent link="gantry_base_link"/>
    <child link="camera_rear_left_corner_link"/>
    <origin rpy="0 0.41887902047863906 -0.8377580409572781" xyz="0.4 9.65 4"/>
  </joint>
  <link name="camera_rear_left_corner_link">
    <visual>
      <geometry>
        <box size="0.085 0.049 0.049"/>
      </geometry>
      <material name="green">
        <color rgba="0 1 0 1"/>
      </material>
    </visual>
  </link>
  <joint name="camera_rear_left_corner_optical_joint" type="fixed">
    <parent link="camera_rear_left_corner_link"/>
    <child link="camera_rear_left_corner_optical_frame"/>
    <origin rpy="-1.5707963267948966 0 -1.5707963267948966" xyz="0 0 0"/>
  </joint>
  <link name="camera_rear_left_corner_optical_frame"/>
  <joint name="camera_rear_right_corner_joint" type="fixed">
    <parent link="gantry_base_link"/>
    <child link="camera_rear_right_corner_link"/>
    <origin rpy="0 0.41887902047863906 0.8377580409572781" xyz="0.4 0.71 4"/>
  </joint>
  <link name="camera_rear_right_corner_link">
    <visual>
      <geometry>
        <box size="0.085 0.049 0.049"/>
      </geometry>
      <material name="green">
        <color rgba="0 1 0 1"/>
      </material>
    </visual>
  </link>
  <joint name="camera_rear_right_corner_optical_joint" type="fixed">
    <parent link="camera_rear_right_corner_link"/>
    <child link="camera_rear_right_corner_optical_frame"/>
    <origin rpy="-1.5707963267948966 0 -1.5707963267948966" xyz="0 0 0"/>
  </joint>
  <link name="camera_rear_right_corner_optical_frame"/>
  <joint name="camera_front_right_corner_joint" type="fixed">
    <parent link="gantry_base_link"/>
    <child link="camera_front_right_corner_link"/>
    <origin rpy="0 0.40142572795869574 2.0943951023931953" xyz="12 0.71 4"/>
  </joint>
  <link name="camera_front_right_corner_link">
    <visual>
      <geometry>
        <box size="0.085 0.049 0.049"/>
      </geometry>
      <material name="green">
        <color rgba="0 1 0 1"/>
      </material>
    </visual>
  </link>
  <joint name="camera_front_right_corner_optical_joint" type="fixed">
    <parent link="camera_front_right_corner_link"/>
    <child link="camera_front_right_corner_optical_frame"/>
    <origin rpy="-1.5707963267948966 0 -1.5707963267948966" xyz="0 0 0"/>
  </joint>
  <link name="camera_front_right_corner_optical_frame"/>
  <joint name="camera_front_left_corner_joint" type="fixed">
    <parent link="gantry_base_link"/>
    <child link="camera_front_left_corner_link"/>
    <origin rpy="0 0.40142572795869574 -2.0943951023931953" xyz="12 9.65 4"/>
  </joint>
  <link name="camera_front_left_corner_link">
    <visual>
      <geometry>
        <box size="0.085 0.049 0.049"/>
      </geometry>
      <material name="green">
        <color rgba="0 1 0 1"/>
      </material>
    </visual>
  </link>
  <joint name="camera_front_left_corner_optical_joint" type="fixed">
    <parent link="camera_front_left_corner_link"/>
    <child link="camera_front_left_corner_optical_frame"/>
    <origin rpy="-1.5707963267948966 0 -1.5707963267948966" xyz="0 0 0"/>
  </joint>
  <link name="camera_front_left_corner_optical_frame"/>
  <joint name="camera_zb_axis_joint" type="fixed">
    <parent link="gantry_reflector_frame"/>
    <child link="camera_zb_axis_link"/>
    <origin rpy="0 1.7453292519943295 0" xyz="0 0 0"/>
  </joint>
  <link name="camera_zb_axis_link">
    <visual>
      <geometry>
        <box size="0.085 0.049 0.049"/>
      </geometry>
      <material name="green">
        <color rgba="0 1 0 1"/>
      </material>
    </visual>
  </link>
  <joint name="camera_zb_axis_optical_joint" type="fixed">
    <parent link="camera_zb_axis_link"/>
    <child link="camera_zb_axis_optical_frame"/>
    <origin rpy="-1.5707963267948966 0 -1.5707963267948966" xyz="0 0 0"/>
  </joint>
  <link name="camera_zb_axis_optical_frame"/>
  <joint name="gantry_base_link_to_jig_jig_base_link" type="fixed">
    <parent link="gantry_base_link"/>
    <child link="jig_base_link"/>
    <origin rpy="0.00012217304763960306 0.002178170906488923 3.137857648990525" xyz="11.429882 6.0046782 0"/>
  </joint>
</robot>
