<?xml version="1.0" ?>
<!-- =================================================================================== -->
<!-- |    This document was autogenerated by xacro from holybro.xacro                  | -->
<!-- |    EDITING THIS FILE BY HAND IS NOT RECOMMENDED                                 | -->
<!-- =================================================================================== -->
<robot name="holybroX500">
  <link name="rotating_link_left">
    <inertial>
      <mass value="0.1"/>
      <inertia ixx="4.322708e-05" ixy="0" ixz="0" iyy="3.75604e-05" iyz="0" izz="3.03708e-05"/>
    </inertial>
    <collision>
      <geometry>
        <box size="0.0385 0.0465 0.055"/>
      </geometry>
    </collision>
    <visual>
      <geometry>
        <mesh filename="meshes\ArmToLimb.stl"/>
      </geometry>
      <material name="darkgray">
        <color rgba="0.2 0.2 0.2 1"/>
      </material>
    </visual>
  </link>
  <link name="rod_link_left">
    <inertial>
      <origin rpy="0 0 0" xyz="0 0 -0.175"/>
      <mass value="0.01"/>
      <inertia ixx="0.00010212333333333332" ixy="0.0" ixz="0.0" iyy="0.00010212333333333332" iyz="0.0" izz="8e-08"/>
    </inertial>
    <collision>
      <origin rpy="0 0 0" xyz="0 0 -0.175"/>
      <geometry>
        <cylinder length="0.35" radius="0.004"/>
      </geometry>
    </collision>
    <visual>
      <origin rpy="0 0 0" xyz="0 0 -0.175"/>
      <geometry>
        <cylinder length="0.35" radius="0.004"/>
      </geometry>
      <material name="darkred">
        <color rgba="0.8 0.2 0.2 1"/>
      </material>
    </visual>
  </link>
  <joint name="servo_move_left" type="revolute">
    <parent link="fixed_base"/>
    <child link="rotating_link_left"/>
    <origin rpy="0 0 1.5708" xyz="0.0 0.054 -0.084"/>
    <axis xyz="0 0 1"/>
    <limit effort="1000.0" lower="-1.57" upper="1.57" velocity="0.5"/>
    <dynamics damping="0.1" friction="0"/>
  </joint>
  <joint name="rod_joint_left" type="fixed">
    <parent link="rotating_link_left"/>
    <child link="rod_link_left"/>
    <origin rpy="-1.5708 0 0" xyz="0.0 0.015 0.01"/>
    <axis xyz="1 0 0"/>
    <limit effort="1000.0" lower="0.0" upper="0.0" velocity="0.5"/>
    <dynamics damping="0.1" friction="0"/>
  </joint>
  <link name="rotating_link_right">
    <inertial>
      <mass value="0.1"/>
      <inertia ixx="4.322708e-05" ixy="0" ixz="0" iyy="3.75604e-05" iyz="0" izz="3.03708e-05"/>
    </inertial>
    <collision>
      <geometry>
        <box size="0.0385 0.0465 0.055"/>
      </geometry>
    </collision>
    <visual>
      <geometry>
        <mesh filename="meshes\ArmToLimb.stl"/>
      </geometry>
      <material name="darkgray">
        <color rgba="0.2 0.2 0.2 1"/>
      </material>
    </visual>
  </link>
  <link name="rod_link_right">
    <inertial>
      <origin rpy="0 0 0" xyz="0 0 -0.175"/>
      <mass value="0.01"/>
      <inertia ixx="0.00010212333333333332" ixy="0.0" ixz="0.0" iyy="0.00010212333333333332" iyz="0.0" izz="8e-08"/>
    </inertial>
    <collision>
      <origin rpy="0 0 0" xyz="0 0 -0.175"/>
      <geometry>
        <cylinder length="0.35" radius="0.004"/>
      </geometry>
    </collision>
    <visual>
      <origin rpy="0 0 0" xyz="0 0 -0.175"/>
      <geometry>
        <cylinder length="0.35" radius="0.004"/>
      </geometry>
      <material name="darkred">
        <color rgba="0.8 0.2 0.2 1"/>
      </material>
    </visual>
  </link>
  <joint name="servo_move_right" type="revolute">
    <parent link="fixed_base"/>
    <child link="rotating_link_right"/>
    <origin rpy="0 0 1.5708" xyz="0.0 -0.054 -0.084"/>
    <axis xyz="0 0 1"/>
    <limit effort="1000.0" lower="-1.57" upper="1.57" velocity="0.5"/>
    <dynamics damping="0.1" friction="0"/>
  </joint>
  <joint name="rod_joint_right" type="fixed">
    <parent link="rotating_link_right"/>
    <child link="rod_link_right"/>
    <origin rpy="-1.5708 0 0" xyz="0.0 0.015 0.01"/>
    <axis xyz="1 0 0"/>
    <limit effort="1000.0" lower="0.0" upper="0.0" velocity="0.5"/>
    <dynamics damping="0.1" friction="0"/>
  </joint>
  <link name="flexible_link_right_1">
    <inertial>
      <mass value="0.0058823529411764705"/>
      <origin rpy="-1.5707963267948966 0 0" xyz="0 0.0066972222222222225 0"/>
      <inertia ixx="6.18828991164367e-07" ixy="0.0" ixz="0.0" iyy="6.18828991164367e-07" iyz="0.0" izz="1.0617647058823529e-06"/>
    </inertial>
    <collision>
      <origin rpy="-1.5707963267948966 0 0" xyz="0 0.0066972222222222225 0"/>
      <geometry>
        <cylinder length="0.013394444444444445" radius="0.018277777777777778"/>
      </geometry>
    </collision>
    <visual>
      <origin rpy="-1.5707963267948966 0 0" xyz="0 0.0066972222222222225 0"/>
      <geometry>
        <cylinder length="0.013394444444444445" radius="0.018277777777777778"/>
      </geometry>
      <material name="darkgray">
        <color rgba="0.2 0.2 0.2 1"/>
      </material>
    </visual>
  </link>
  <link name="flexible_link_right_18">
    <inertial>
      <mass value="0.0058823529411764705"/>
      <origin rpy="-1.5707963267948966 0 0" xyz="0 0.0066972222222222225 0"/>
      <inertia ixx="1.4088781469377874e-07" ixy="0.0" ixz="0.0" iyy="1.4088781469377874e-07" iyz="0.0" izz="1.0588235294117647e-07"/>
    </inertial>
    <collision>
      <origin rpy="-1.5707963267948966 0 0" xyz="0 0.0066972222222222225 0"/>
      <geometry>
        <cylinder length="0.013394444444444445" radius="0.006"/>
      </geometry>
    </collision>
    <visual>
      <origin rpy="-1.5707963267948966 0 0" xyz="0 0.0066972222222222225 0"/>
      <geometry>
        <cylinder length="0.013394444444444445" radius="0.006"/>
      </geometry>
      <material name="darkgray">
        <color rgba="0.2 0.2 0.2 1"/>
      </material>
    </visual>
  </link>
  <gazebo reference="flex_joint_right_from_17_to_18">
    <implicitSpringDamper>0</implicitSpringDamper>
    <springReference>0</springReference>
    <springStiffness>0.5</springStiffness>
  </gazebo>
  <joint name="flex_joint_right_from_17_to_18" type="revolute">
    <parent link="flexible_link_right_17"/>
    <child link="flexible_link_right_18"/>
    <origin rpy="0 0 0" xyz="0 0.013394444444444445 0"/>
    <axis xyz="0 0 1"/>
    <limit effort="1000.0" lower="-1e+16" upper="1e+16" velocity="0.5"/>
    <dynamics damping="0.1" friction="0"/>
  </joint>
  <link name="flexible_link_right_17">
    <inertial>
      <mass value="0.0058823529411764705"/>
      <origin rpy="-1.5707963267948966 0 0" xyz="0 0.0066972222222222225 0"/>
      <inertia ixx="1.54399978818688e-07" ixy="0.0" ixz="0.0" iyy="1.54399978818688e-07" iyz="0.0" izz="1.3290668119099497e-07"/>
    </inertial>
    <collision>
      <origin rpy="-1.5707963267948966 0 0" xyz="0 0.0066972222222222225 0"/>
      <geometry>
        <cylinder length="0.013394444444444445" radius="0.006722222222222223"/>
      </geometry>
    </collision>
    <visual>
      <origin rpy="-1.5707963267948966 0 0" xyz="0 0.0066972222222222225 0"/>
      <geometry>
        <cylinder length="0.013394444444444445" radius="0.006722222222222223"/>
      </geometry>
      <material name="darkgray">
        <color rgba="0.2 0.2 0.2 1"/>
      </material>
    </visual>
  </link>
  <gazebo reference="flex_joint_right_from_16_to_17">
    <implicitSpringDamper>0</implicitSpringDamper>
    <springReference>0</springReference>
    <springStiffness>0.5</springStiffness>
  </gazebo>
  <joint name="flex_joint_right_from_16_to_17" type="revolute">
    <parent link="flexible_link_right_16"/>
    <child link="flexible_link_right_17"/>
    <origin rpy="0 0 0" xyz="0 0.013394444444444445 0"/>
    <axis xyz="0 0 1"/>
    <limit effort="1000.0" lower="-1e+16" upper="1e+16" velocity="0.5"/>
    <dynamics damping="0.1" friction="0"/>
  </joint>
  <link name="flexible_link_right_16">
    <inertial>
      <mass value="0.0058823529411764705"/>
      <origin rpy="-1.5707963267948966 0 0" xyz="0 0.0066972222222222225 0"/>
      <inertia ixx="1.6944627511498426e-07" ixy="0.0" ixz="0.0" iyy="1.6944627511498426e-07" iyz="0.0" izz="1.629992737835875e-07"/>
    </inertial>
    <collision>
      <origin rpy="-1.5707963267948966 0 0" xyz="0 0.0066972222222222225 0"/>
      <geometry>
        <cylinder length="0.013394444444444445" radius="0.0074444444444444445"/>
      </geometry>
    </collision>
    <visual>
      <origin rpy="-1.5707963267948966 0 0" xyz="0 0.0066972222222222225 0"/>
      <geometry>
        <cylinder length="0.013394444444444445" radius="0.0074444444444444445"/>
      </geometry>
      <material name="darkgray">
        <color rgba="0.2 0.2 0.2 1"/>
      </material>
    </visual>
  </link>
  <gazebo reference="flex_joint_right_from_15_to_16">
    <implicitSpringDamper>0</implicitSpringDamper>
    <springReference>0</springReference>
    <springStiffness>0.5</springStiffness>
  </gazebo>
  <joint name="flex_joint_right_from_15_to_16" type="revolute">
    <parent link="flexible_link_right_15"/>
    <child link="flexible_link_right_16"/>
    <origin rpy="0 0 0" xyz="0 0.013394444444444445 0"/>
    <axis xyz="0 0 1"/>
    <limit effort="1000.0" lower="-1e+16" upper="1e+16" velocity="0.5"/>
    <dynamics damping="0.1" friction="0"/>
  </joint>
  <link name="flexible_link_right_15">
    <inertial>
      <mass value="0.0058823529411764705"/>
      <origin rpy="-1.5707963267948966 0 0" xyz="0 0.0066972222222222225 0"/>
      <inertia ixx="1.8602670358266762e-07" ixy="0.0" ixz="0.0" iyy="1.8602670358266762e-07" iyz="0.0" izz="1.961601307189542e-07"/>
    </inertial>
    <collision>
      <origin rpy="-1.5707963267948966 0 0" xyz="0 0.0066972222222222225 0"/>
      <geometry>
        <cylinder length="0.013394444444444445" radius="0.008166666666666666"/>
      </geometry>
    </collision>
    <visual>
      <origin rpy="-1.5707963267948966 0 0" xyz="0 0.0066972222222222225 0"/>
      <geometry>
        <cylinder length="0.013394444444444445" radius="0.008166666666666666"/>
      </geometry>
      <material name="darkgray">
        <color rgba="0.2 0.2 0.2 1"/>
      </material>
    </visual>
  </link>
  <gazebo reference="flex_joint_right_from_14_to_15">
    <implicitSpringDamper>0</implicitSpringDamper>
    <springReference>0</springReference>
    <springStiffness>0.5</springStiffness>
  </gazebo>
  <joint name="flex_joint_right_from_14_to_15" type="revolute">
    <parent link="flexible_link_right_14"/>
    <child link="flexible_link_right_15"/>
    <origin rpy="0 0 0" xyz="0 0.013394444444444445 0"/>
    <axis xyz="0 0 1"/>
    <limit effort="1000.0" lower="-1e+16" upper="1e+16" velocity="0.5"/>
    <dynamics damping="0.1" friction="0"/>
  </joint>
  <link name="flexible_link_right_14">
    <inertial>
      <mass value="0.0058823529411764705"/>
      <origin rpy="-1.5707963267948966 0 0" xyz="0 0.0066972222222222225 0"/>
      <inertia ixx="2.041412642217381e-07" ixy="0.0" ixz="0.0" iyy="2.041412642217381e-07" iyz="0.0" izz="2.3238925199709512e-07"/>
    </inertial>
    <collision>
      <origin rpy="-1.5707963267948966 0 0" xyz="0 0.0066972222222222225 0"/>
      <geometry>
        <cylinder length="0.013394444444444445" radius="0.008888888888888889"/>
      </geometry>
    </collision>
    <visual>
      <origin rpy="-1.5707963267948966 0 0" xyz="0 0.0066972222222222225 0"/>
      <geometry>
        <cylinder length="0.013394444444444445" radius="0.008888888888888889"/>
      </geometry>
      <material name="darkgray">
        <color rgba="0.2 0.2 0.2 1"/>
      </material>
    </visual>
  </link>
  <gazebo reference="flex_joint_right_from_13_to_14">
    <implicitSpringDamper>0</implicitSpringDamper>
    <springReference>0</springReference>
    <springStiffness>0.5</springStiffness>
  </gazebo>
  <joint name="flex_joint_right_from_13_to_14" type="revolute">
    <parent link="flexible_link_right_13"/>
    <child link="flexible_link_right_14"/>
    <origin rpy="0 0 0" xyz="0 0.013394444444444445 0"/>
    <axis xyz="0 0 1"/>
    <limit effort="1000.0" lower="-1e+16" upper="1e+16" velocity="0.5"/>
    <dynamics damping="0.1" friction="0"/>
  </joint>
  <link name="flexible_link_right_13">
    <inertial>
      <mass value="0.0058823529411764705"/>
      <origin rpy="-1.5707963267948966 0 0" xyz="0 0.0066972222222222225 0"/>
      <inertia ixx="2.2378995703219564e-07" ixy="0.0" ixz="0.0" iyy="2.2378995703219564e-07" iyz="0.0" izz="2.716866376180102e-07"/>
    </inertial>
    <collision>
      <origin rpy="-1.5707963267948966 0 0" xyz="0 0.0066972222222222225 0"/>
      <geometry>
        <cylinder length="0.013394444444444445" radius="0.009611111111111112"/>
      </geometry>
    </collision>
    <visual>
      <origin rpy="-1.5707963267948966 0 0" xyz="0 0.0066972222222222225 0"/>
      <geometry>
        <cylinder length="0.013394444444444445" radius="0.009611111111111112"/>
      </geometry>
      <material name="darkgray">
        <color rgba="0.2 0.2 0.2 1"/>
      </material>
    </visual>
  </link>
  <gazebo reference="flex_joint_right_from_12_to_13">
    <implicitSpringDamper>0</implicitSpringDamper>
    <springReference>0</springReference>
    <springStiffness>0.5</springStiffness>
  </gazebo>
  <joint name="flex_joint_right_from_12_to_13" type="revolute">
    <parent link="flexible_link_right_12"/>
    <child link="flexible_link_right_13"/>
    <origin rpy="0 0 0" xyz="0 0.013394444444444445 0"/>
    <axis xyz="0 0 1"/>
    <limit effort="1000.0" lower="-1e+16" upper="1e+16" velocity="0.5"/>
    <dynamics damping="0.1" friction="0"/>
  </joint>
  <link name="flexible_link_right_12">
    <inertial>
      <mass value="0.0058823529411764705"/>
      <origin rpy="-1.5707963267948966 0 0" xyz="0 0.0066972222222222225 0"/>
      <inertia ixx="2.449727820140402e-07" ixy="0.0" ixz="0.0" iyy="2.449727820140402e-07" iyz="0.0" izz="3.140522875816993e-07"/>
    </inertial>
    <collision>
      <origin rpy="-1.5707963267948966 0 0" xyz="0 0.0066972222222222225 0"/>
      <geometry>
        <cylinder length="0.013394444444444445" radius="0.010333333333333333"/>
      </geometry>
    </collision>
    <visual>
      <origin rpy="-1.5707963267948966 0 0" xyz="0 0.0066972222222222225 0"/>
      <geometry>
        <cylinder length="0.013394444444444445" radius="0.010333333333333333"/>
      </geometry>
      <material name="darkgray">
        <color rgba="0.2 0.2 0.2 1"/>
      </material>
    </visual>
  </link>
  <gazebo reference="flex_joint_right_from_11_to_12">
    <implicitSpringDamper>0</implicitSpringDamper>
    <springReference>0</springReference>
    <springStiffness>0.5</springStiffness>
  </gazebo>
  <joint name="flex_joint_right_from_11_to_12" type="revolute">
    <parent link="flexible_link_right_11"/>
    <child link="flexible_link_right_12"/>
    <origin rpy="0 0 0" xyz="0 0.013394444444444445 0"/>
    <axis xyz="0 0 1"/>
    <limit effort="1000.0" lower="-1e+16" upper="1e+16" velocity="0.5"/>
    <dynamics damping="0.1" friction="0"/>
  </joint>
  <link name="flexible_link_right_11">
    <inertial>
      <mass value="0.0058823529411764705"/>
      <origin rpy="-1.5707963267948966 0 0" xyz="0 0.0066972222222222225 0"/>
      <inertia ixx="2.676897391672718e-07" ixy="0.0" ixz="0.0" iyy="2.676897391672718e-07" iyz="0.0" izz="3.5948620188816257e-07"/>
    </inertial>
    <collision>
      <origin rpy="-1.5707963267948966 0 0" xyz="0 0.0066972222222222225 0"/>
      <geometry>
        <cylinder length="0.013394444444444445" radius="0.011055555555555555"/>
      </geometry>
    </collision>
    <visual>
      <origin rpy="-1.5707963267948966 0 0" xyz="0 0.0066972222222222225 0"/>
      <geometry>
        <cylinder length="0.013394444444444445" radius="0.011055555555555555"/>
      </geometry>
      <material name="darkgray">
        <color rgba="0.2 0.2 0.2 1"/>
      </material>
    </visual>
  </link>
  <gazebo reference="flex_joint_right_from_10_to_11">
    <implicitSpringDamper>0</implicitSpringDamper>
    <springReference>0</springReference>
    <springStiffness>0.5</springStiffness>
  </gazebo>
  <joint name="flex_joint_right_from_10_to_11" type="revolute">
    <parent link="flexible_link_right_10"/>
    <child link="flexible_link_right_11"/>
    <origin rpy="0 0 0" xyz="0 0.013394444444444445 0"/>
    <axis xyz="0 0 1"/>
    <limit effort="1000.0" lower="-1e+16" upper="1e+16" velocity="0.5"/>
    <dynamics damping="0.1" friction="0"/>
  </joint>
  <link name="flexible_link_right_10">
    <inertial>
      <mass value="0.0058823529411764705"/>
      <origin rpy="-1.5707963267948966 0 0" xyz="0 0.0066972222222222225 0"/>
      <inertia ixx="2.919408284918906e-07" ixy="0.0" ixz="0.0" iyy="2.919408284918906e-07" iyz="0.0" izz="4.0798838053740015e-07"/>
    </inertial>
    <collision>
      <origin rpy="-1.5707963267948966 0 0" xyz="0 0.0066972222222222225 0"/>
      <geometry>
        <cylinder length="0.013394444444444445" radius="0.011777777777777778"/>
      </geometry>
    </collision>
    <visual>
      <origin rpy="-1.5707963267948966 0 0" xyz="0 0.0066972222222222225 0"/>
      <geometry>
        <cylinder length="0.013394444444444445" radius="0.011777777777777778"/>
      </geometry>
      <material name="darkgray">
        <color rgba="0.2 0.2 0.2 1"/>
      </material>
    </visual>
  </link>
  <gazebo reference="flex_joint_right_from_9_to_10">
    <implicitSpringDamper>0</implicitSpringDamper>
    <springReference>0</springReference>
    <springStiffness>0.5</springStiffness>
  </gazebo>
  <joint name="flex_joint_right_from_9_to_10" type="revolute">
    <parent link="flexible_link_right_9"/>
    <child link="flexible_link_right_10"/>
    <origin rpy="0 0 0" xyz="0 0.013394444444444445 0"/>
    <axis xyz="0 0 1"/>
    <limit effort="1000.0" lower="-1e+16" upper="1e+16" velocity="0.5"/>
    <dynamics damping="0.1" friction="0"/>
  </joint>
  <link name="flexible_link_right_9">
    <inertial>
      <mass value="0.0058823529411764705"/>
      <origin rpy="-1.5707963267948966 0 0" xyz="0 0.0066972222222222225 0"/>
      <inertia ixx="3.177260499878964e-07" ixy="0.0" ixz="0.0" iyy="3.177260499878964e-07" iyz="0.0" izz="4.5955882352941183e-07"/>
    </inertial>
    <collision>
      <origin rpy="-1.5707963267948966 0 0" xyz="0 0.0066972222222222225 0"/>
      <geometry>
        <cylinder length="0.013394444444444445" radius="0.0125"/>
      </geometry>
    </collision>
    <visual>
      <origin rpy="-1.5707963267948966 0 0" xyz="0 0.0066972222222222225 0"/>
      <geometry>
        <cylinder length="0.013394444444444445" radius="0.0125"/>
      </geometry>
      <material name="darkgray">
        <color rgba="0.2 0.2 0.2 1"/>
      </material>
    </visual>
  </link>
  <gazebo reference="flex_joint_right_from_8_to_9">
    <implicitSpringDamper>0</implicitSpringDamper>
    <springReference>0</springReference>
    <springStiffness>0.5</springStiffness>
  </gazebo>
  <joint name="flex_joint_right_from_8_to_9" type="revolute">
    <parent link="flexible_link_right_8"/>
    <child link="flexible_link_right_9"/>
    <origin rpy="0 0 0" xyz="0 0.013394444444444445 0"/>
    <axis xyz="0 0 1"/>
    <limit effort="1000.0" lower="-1e+16" upper="1e+16" velocity="0.5"/>
    <dynamics damping="0.1" friction="0"/>
  </joint>
  <link name="flexible_link_right_8">
    <inertial>
      <mass value="0.0058823529411764705"/>
      <origin rpy="-1.5707963267948966 0 0" xyz="0 0.0066972222222222225 0"/>
      <inertia ixx="3.450454036552893e-07" ixy="0.0" ixz="0.0" iyy="3.450454036552893e-07" iyz="0.0" izz="5.141975308641976e-07"/>
    </inertial>
    <collision>
      <origin rpy="-1.5707963267948966 0 0" xyz="0 0.0066972222222222225 0"/>
      <geometry>
        <cylinder length="0.013394444444444445" radius="0.013222222222222222"/>
      </geometry>
    </collision>
    <visual>
      <origin rpy="-1.5707963267948966 0 0" xyz="0 0.0066972222222222225 0"/>
      <geometry>
        <cylinder length="0.013394444444444445" radius="0.013222222222222222"/>
      </geometry>
      <material name="darkgray">
        <color rgba="0.2 0.2 0.2 1"/>
      </material>
    </visual>
  </link>
  <gazebo reference="flex_joint_right_from_7_to_8">
    <implicitSpringDamper>0</implicitSpringDamper>
    <springReference>0</springReference>
    <springStiffness>0.5</springStiffness>
  </gazebo>
  <joint name="flex_joint_right_from_7_to_8" type="revolute">
    <parent link="flexible_link_right_7"/>
    <child link="flexible_link_right_8"/>
    <origin rpy="0 0 0" xyz="0 0.013394444444444445 0"/>
    <axis xyz="0 0 1"/>
    <limit effort="1000.0" lower="-1e+16" upper="1e+16" velocity="0.5"/>
    <dynamics damping="0.1" friction="0"/>
  </joint>
  <link name="flexible_link_right_7">
    <inertial>
      <mass value="0.0058823529411764705"/>
      <origin rpy="-1.5707963267948966 0 0" xyz="0 0.0066972222222222225 0"/>
      <inertia ixx="3.7389888949406916e-07" ixy="0.0" ixz="0.0" iyy="3.7389888949406916e-07" iyz="0.0" izz="5.719045025417573e-07"/>
    </inertial>
    <collision>
      <origin rpy="-1.5707963267948966 0 0" xyz="0 0.0066972222222222225 0"/>
      <geometry>
        <cylinder length="0.013394444444444445" radius="0.013944444444444443"/>
      </geometry>
    </collision>
    <visual>
      <origin rpy="-1.5707963267948966 0 0" xyz="0 0.0066972222222222225 0"/>
      <geometry>
        <cylinder length="0.013394444444444445" radius="0.013944444444444443"/>
      </geometry>
      <material name="darkgray">
        <color rgba="0.2 0.2 0.2 1"/>
      </material>
    </visual>
  </link>
  <gazebo reference="flex_joint_right_from_6_to_7">
    <implicitSpringDamper>0</implicitSpringDamper>
    <springReference>0</springReference>
    <springStiffness>0.5</springStiffness>
  </gazebo>
  <joint name="flex_joint_right_from_6_to_7" type="revolute">
    <parent link="flexible_link_right_6"/>
    <child link="flexible_link_right_7"/>
    <origin rpy="0 0 0" xyz="0 0.013394444444444445 0"/>
    <axis xyz="0 0 1"/>
    <limit effort="1000.0" lower="-1e+16" upper="1e+16" velocity="0.5"/>
    <dynamics damping="0.1" friction="0"/>
  </joint>
  <link name="flexible_link_right_6">
    <inertial>
      <mass value="0.0058823529411764705"/>
      <origin rpy="-1.5707963267948966 0 0" xyz="0 0.0066972222222222225 0"/>
      <inertia ixx="4.0428650750423624e-07" ixy="0.0" ixz="0.0" iyy="4.0428650750423624e-07" iyz="0.0" izz="6.326797385620915e-07"/>
    </inertial>
    <collision>
      <origin rpy="-1.5707963267948966 0 0" xyz="0 0.0066972222222222225 0"/>
      <geometry>
        <cylinder length="0.013394444444444445" radius="0.014666666666666666"/>
      </geometry>
    </collision>
    <visual>
      <origin rpy="-1.5707963267948966 0 0" xyz="0 0.0066972222222222225 0"/>
      <geometry>
        <cylinder length="0.013394444444444445" radius="0.014666666666666666"/>
      </geometry>
      <material name="darkgray">
        <color rgba="0.2 0.2 0.2 1"/>
      </material>
    </visual>
  </link>
  <gazebo reference="flex_joint_right_from_5_to_6">
    <implicitSpringDamper>0</implicitSpringDamper>
    <springReference>0</springReference>
    <springStiffness>0.5</springStiffness>
  </gazebo>
  <joint name="flex_joint_right_from_5_to_6" type="revolute">
    <parent link="flexible_link_right_5"/>
    <child link="flexible_link_right_6"/>
    <origin rpy="0 0 0" xyz="0 0.013394444444444445 0"/>
    <axis xyz="0 0 1"/>
    <limit effort="1000.0" lower="-1e+16" upper="1e+16" velocity="0.5"/>
    <dynamics damping="0.1" friction="0"/>
  </joint>
  <link name="flexible_link_right_5">
    <inertial>
      <mass value="0.0058823529411764705"/>
      <origin rpy="-1.5707963267948966 0 0" xyz="0 0.0066972222222222225 0"/>
      <inertia ixx="4.362082576857904e-07" ixy="0.0" ixz="0.0" iyy="4.362082576857904e-07" iyz="0.0" izz="6.965232389251998e-07"/>
    </inertial>
    <collision>
      <origin rpy="-1.5707963267948966 0 0" xyz="0 0.0066972222222222225 0"/>
      <geometry>
        <cylinder length="0.013394444444444445" radius="0.01538888888888889"/>
      </geometry>
    </collision>
    <visual>
      <origin rpy="-1.5707963267948966 0 0" xyz="0 0.0066972222222222225 0"/>
      <geometry>
        <cylinder length="0.013394444444444445" radius="0.01538888888888889"/>
      </geometry>
      <material name="darkgray">
        <color rgba="0.2 0.2 0.2 1"/>
      </material>
    </visual>
  </link>
  <gazebo reference="flex_joint_right_from_4_to_5">
    <implicitSpringDamper>0</implicitSpringDamper>
    <springReference>0</springReference>
    <springStiffness>0.5</springStiffness>
  </gazebo>
  <joint name="flex_joint_right_from_4_to_5" type="revolute">
    <parent link="flexible_link_right_4"/>
    <child link="flexible_link_right_5"/>
    <origin rpy="0 0 0" xyz="0 0.013394444444444445 0"/>
    <axis xyz="0 0 1"/>
    <limit effort="1000.0" lower="-1e+16" upper="1e+16" velocity="0.5"/>
    <dynamics damping="0.1" friction="0"/>
  </joint>
  <link name="flexible_link_right_4">
    <inertial>
      <mass value="0.0058823529411764705"/>
      <origin rpy="-1.5707963267948966 0 0" xyz="0 0.0066972222222222225 0"/>
      <inertia ixx="4.696641400387315e-07" ixy="0.0" ixz="0.0" iyy="4.696641400387315e-07" iyz="0.0" izz="7.63435003631082e-07"/>
    </inertial>
    <collision>
      <origin rpy="-1.5707963267948966 0 0" xyz="0 0.0066972222222222225 0"/>
      <geometry>
        <cylinder length="0.013394444444444445" radius="0.01611111111111111"/>
      </geometry>
    </collision>
    <visual>
      <origin rpy="-1.5707963267948966 0 0" xyz="0 0.0066972222222222225 0"/>
      <geometry>
        <cylinder length="0.013394444444444445" radius="0.01611111111111111"/>
      </geometry>
      <material name="darkgray">
        <color rgba="0.2 0.2 0.2 1"/>
      </material>
    </visual>
  </link>
  <gazebo reference="flex_joint_right_from_3_to_4">
    <implicitSpringDamper>0</implicitSpringDamper>
    <springReference>0</springReference>
    <springStiffness>0.5</springStiffness>
  </gazebo>
  <joint name="flex_joint_right_from_3_to_4" type="revolute">
    <parent link="flexible_link_right_3"/>
    <child link="flexible_link_right_4"/>
    <origin rpy="0 0 0" xyz="0 0.013394444444444445 0"/>
    <axis xyz="0 0 1"/>
    <limit effort="1000.0" lower="-1e+16" upper="1e+16" velocity="0.5"/>
    <dynamics damping="0.1" friction="0"/>
  </joint>
  <link name="flexible_link_right_3">
    <inertial>
      <mass value="0.0058823529411764705"/>
      <origin rpy="-1.5707963267948966 0 0" xyz="0 0.0066972222222222225 0"/>
      <inertia ixx="5.046541545630597e-07" ixy="0.0" ixz="0.0" iyy="5.046541545630597e-07" iyz="0.0" izz="8.334150326797384e-07"/>
    </inertial>
    <collision>
      <origin rpy="-1.5707963267948966 0 0" xyz="0 0.0066972222222222225 0"/>
      <geometry>
        <cylinder length="0.013394444444444445" radius="0.016833333333333332"/>
      </geometry>
    </collision>
    <visual>
      <origin rpy="-1.5707963267948966 0 0" xyz="0 0.0066972222222222225 0"/>
      <geometry>
        <cylinder length="0.013394444444444445" radius="0.016833333333333332"/>
      </geometry>
      <material name="darkgray">
        <color rgba="0.2 0.2 0.2 1"/>
      </material>
    </visual>
  </link>
  <gazebo reference="flex_joint_right_from_2_to_3">
    <implicitSpringDamper>0</implicitSpringDamper>
    <springReference>0</springReference>
    <springStiffness>0.5</springStiffness>
  </gazebo>
  <joint name="flex_joint_right_from_2_to_3" type="revolute">
    <parent link="flexible_link_right_2"/>
    <child link="flexible_link_right_3"/>
    <origin rpy="0 0 0" xyz="0 0.013394444444444445 0"/>
    <axis xyz="0 0 1"/>
    <limit effort="1000.0" lower="-1e+16" upper="1e+16" velocity="0.5"/>
    <dynamics damping="0.1" friction="0"/>
  </joint>
  <link name="flexible_link_right_2">
    <inertial>
      <mass value="0.0058823529411764705"/>
      <origin rpy="-1.5707963267948966 0 0" xyz="0 0.0066972222222222225 0"/>
      <inertia ixx="5.41178301258775e-07" ixy="0.0" ixz="0.0" iyy="5.41178301258775e-07" iyz="0.0" izz="9.06463326071169e-07"/>
    </inertial>
    <collision>
      <origin rpy="-1.5707963267948966 0 0" xyz="0 0.0066972222222222225 0"/>
      <geometry>
        <cylinder length="0.013394444444444445" radius="0.017555555555555553"/>
      </geometry>
    </collision>
    <visual>
      <origin rpy="-1.5707963267948966 0 0" xyz="0 0.0066972222222222225 0"/>
      <geometry>
        <cylinder length="0.013394444444444445" radius="0.017555555555555553"/>
      </geometry>
      <material name="darkgray">
        <color rgba="0.2 0.2 0.2 1"/>
      </material>
    </visual>
  </link>
  <gazebo reference="flex_joint_right_from_1_to_2">
    <implicitSpringDamper>0</implicitSpringDamper>
    <springReference>0</springReference>
    <springStiffness>0.5</springStiffness>
  </gazebo>
  <joint name="flex_joint_right_from_1_to_2" type="revolute">
    <parent link="flexible_link_right_1"/>
    <child link="flexible_link_right_2"/>
    <origin rpy="0 0 0" xyz="0 0.013394444444444445 0"/>
    <axis xyz="0 0 1"/>
    <limit effort="1000.0" lower="-1e+16" upper="1e+16" velocity="0.5"/>
    <dynamics damping="0.1" friction="0"/>
  </joint>
  <link name="flexible_link_left_1">
    <inertial>
      <mass value="0.0058823529411764705"/>
      <origin rpy="-1.5707963267948966 0 0" xyz="0 0.0066972222222222225 0"/>
      <inertia ixx="6.18828991164367e-07" ixy="0.0" ixz="0.0" iyy="6.18828991164367e-07" iyz="0.0" izz="1.0617647058823529e-06"/>
    </inertial>
    <collision>
      <origin rpy="-1.5707963267948966 0 0" xyz="0 0.0066972222222222225 0"/>
      <geometry>
        <cylinder length="0.013394444444444445" radius="0.018277777777777778"/>
      </geometry>
    </collision>
    <visual>
      <origin rpy="-1.5707963267948966 0 0" xyz="0 0.0066972222222222225 0"/>
      <geometry>
        <cylinder length="0.013394444444444445" radius="0.018277777777777778"/>
      </geometry>
      <material name="darkgray">
        <color rgba="0.2 0.2 0.2 1"/>
      </material>
    </visual>
  </link>
  <link name="flexible_link_left_18">
    <inertial>
      <mass value="0.0058823529411764705"/>
      <origin rpy="-1.5707963267948966 0 0" xyz="0 0.0066972222222222225 0"/>
      <inertia ixx="1.4088781469377874e-07" ixy="0.0" ixz="0.0" iyy="1.4088781469377874e-07" iyz="0.0" izz="1.0588235294117647e-07"/>
    </inertial>
    <collision>
      <origin rpy="-1.5707963267948966 0 0" xyz="0 0.0066972222222222225 0"/>
      <geometry>
        <cylinder length="0.013394444444444445" radius="0.006"/>
      </geometry>
    </collision>
    <visual>
      <origin rpy="-1.5707963267948966 0 0" xyz="0 0.0066972222222222225 0"/>
      <geometry>
        <cylinder length="0.013394444444444445" radius="0.006"/>
      </geometry>
      <material name="darkgray">
        <color rgba="0.2 0.2 0.2 1"/>
      </material>
    </visual>
  </link>
  <gazebo reference="flex_joint_left_from_17_to_18">
    <implicitSpringDamper>0</implicitSpringDamper>
    <springReference>0</springReference>
    <springStiffness>0.5</springStiffness>
  </gazebo>
  <joint name="flex_joint_left_from_17_to_18" type="revolute">
    <parent link="flexible_link_left_17"/>
    <child link="flexible_link_left_18"/>
    <origin rpy="0 0 0" xyz="0 0.013394444444444445 0"/>
    <axis xyz="0 0 1"/>
    <limit effort="1000.0" lower="-1e+16" upper="1e+16" velocity="0.5"/>
    <dynamics damping="0.1" friction="0"/>
  </joint>
  <link name="flexible_link_left_17">
    <inertial>
      <mass value="0.0058823529411764705"/>
      <origin rpy="-1.5707963267948966 0 0" xyz="0 0.0066972222222222225 0"/>
      <inertia ixx="1.54399978818688e-07" ixy="0.0" ixz="0.0" iyy="1.54399978818688e-07" iyz="0.0" izz="1.3290668119099497e-07"/>
    </inertial>
    <collision>
      <origin rpy="-1.5707963267948966 0 0" xyz="0 0.0066972222222222225 0"/>
      <geometry>
        <cylinder length="0.013394444444444445" radius="0.006722222222222223"/>
      </geometry>
    </collision>
    <visual>
      <origin rpy="-1.5707963267948966 0 0" xyz="0 0.0066972222222222225 0"/>
      <geometry>
        <cylinder length="0.013394444444444445" radius="0.006722222222222223"/>
      </geometry>
      <material name="darkgray">
        <color rgba="0.2 0.2 0.2 1"/>
      </material>
    </visual>
  </link>
  <gazebo reference="flex_joint_left_from_16_to_17">
    <implicitSpringDamper>0</implicitSpringDamper>
    <springReference>0</springReference>
    <springStiffness>0.5</springStiffness>
  </gazebo>
  <joint name="flex_joint_left_from_16_to_17" type="revolute">
    <parent link="flexible_link_left_16"/>
    <child link="flexible_link_left_17"/>
    <origin rpy="0 0 0" xyz="0 0.013394444444444445 0"/>
    <axis xyz="0 0 1"/>
    <limit effort="1000.0" lower="-1e+16" upper="1e+16" velocity="0.5"/>
    <dynamics damping="0.1" friction="0"/>
  </joint>
  <link name="flexible_link_left_16">
    <inertial>
      <mass value="0.0058823529411764705"/>
      <origin rpy="-1.5707963267948966 0 0" xyz="0 0.0066972222222222225 0"/>
      <inertia ixx="1.6944627511498426e-07" ixy="0.0" ixz="0.0" iyy="1.6944627511498426e-07" iyz="0.0" izz="1.629992737835875e-07"/>
    </inertial>
    <collision>
      <origin rpy="-1.5707963267948966 0 0" xyz="0 0.0066972222222222225 0"/>
      <geometry>
        <cylinder length="0.013394444444444445" radius="0.0074444444444444445"/>
      </geometry>
    </collision>
    <visual>
      <origin rpy="-1.5707963267948966 0 0" xyz="0 0.0066972222222222225 0"/>
      <geometry>
        <cylinder length="0.013394444444444445" radius="0.0074444444444444445"/>
      </geometry>
      <material name="darkgray">
        <color rgba="0.2 0.2 0.2 1"/>
      </material>
    </visual>
  </link>
  <gazebo reference="flex_joint_left_from_15_to_16">
    <implicitSpringDamper>0</implicitSpringDamper>
    <springReference>0</springReference>
    <springStiffness>0.5</springStiffness>
  </gazebo>
  <joint name="flex_joint_left_from_15_to_16" type="revolute">
    <parent link="flexible_link_left_15"/>
    <child link="flexible_link_left_16"/>
    <origin rpy="0 0 0" xyz="0 0.013394444444444445 0"/>
    <axis xyz="0 0 1"/>
    <limit effort="1000.0" lower="-1e+16" upper="1e+16" velocity="0.5"/>
    <dynamics damping="0.1" friction="0"/>
  </joint>
  <link name="flexible_link_left_15">
    <inertial>
      <mass value="0.0058823529411764705"/>
      <origin rpy="-1.5707963267948966 0 0" xyz="0 0.0066972222222222225 0"/>
      <inertia ixx="1.8602670358266762e-07" ixy="0.0" ixz="0.0" iyy="1.8602670358266762e-07" iyz="0.0" izz="1.961601307189542e-07"/>
    </inertial>
    <collision>
      <origin rpy="-1.5707963267948966 0 0" xyz="0 0.0066972222222222225 0"/>
      <geometry>
        <cylinder length="0.013394444444444445" radius="0.008166666666666666"/>
      </geometry>
    </collision>
    <visual>
      <origin rpy="-1.5707963267948966 0 0" xyz="0 0.0066972222222222225 0"/>
      <geometry>
        <cylinder length="0.013394444444444445" radius="0.008166666666666666"/>
      </geometry>
      <material name="darkgray">
        <color rgba="0.2 0.2 0.2 1"/>
      </material>
    </visual>
  </link>
  <gazebo reference="flex_joint_left_from_14_to_15">
    <implicitSpringDamper>0</implicitSpringDamper>
    <springReference>0</springReference>
    <springStiffness>0.5</springStiffness>
  </gazebo>
  <joint name="flex_joint_left_from_14_to_15" type="revolute">
    <parent link="flexible_link_left_14"/>
    <child link="flexible_link_left_15"/>
    <origin rpy="0 0 0" xyz="0 0.013394444444444445 0"/>
    <axis xyz="0 0 1"/>
    <limit effort="1000.0" lower="-1e+16" upper="1e+16" velocity="0.5"/>
    <dynamics damping="0.1" friction="0"/>
  </joint>
  <link name="flexible_link_left_14">
    <inertial>
      <mass value="0.0058823529411764705"/>
      <origin rpy="-1.5707963267948966 0 0" xyz="0 0.0066972222222222225 0"/>
      <inertia ixx="2.041412642217381e-07" ixy="0.0" ixz="0.0" iyy="2.041412642217381e-07" iyz="0.0" izz="2.3238925199709512e-07"/>
    </inertial>
    <collision>
      <origin rpy="-1.5707963267948966 0 0" xyz="0 0.0066972222222222225 0"/>
      <geometry>
        <cylinder length="0.013394444444444445" radius="0.008888888888888889"/>
      </geometry>
    </collision>
    <visual>
      <origin rpy="-1.5707963267948966 0 0" xyz="0 0.0066972222222222225 0"/>
      <geometry>
        <cylinder length="0.013394444444444445" radius="0.008888888888888889"/>
      </geometry>
      <material name="darkgray">
        <color rgba="0.2 0.2 0.2 1"/>
      </material>
    </visual>
  </link>
  <gazebo reference="flex_joint_left_from_13_to_14">
    <implicitSpringDamper>0</implicitSpringDamper>
    <springReference>0</springReference>
    <springStiffness>0.5</springStiffness>
  </gazebo>
  <joint name="flex_joint_left_from_13_to_14" type="revolute">
    <parent link="flexible_link_left_13"/>
    <child link="flexible_link_left_14"/>
    <origin rpy="0 0 0" xyz="0 0.013394444444444445 0"/>
    <axis xyz="0 0 1"/>
    <limit effort="1000.0" lower="-1e+16" upper="1e+16" velocity="0.5"/>
    <dynamics damping="0.1" friction="0"/>
  </joint>
  <link name="flexible_link_left_13">
    <inertial>
      <mass value="0.0058823529411764705"/>
      <origin rpy="-1.5707963267948966 0 0" xyz="0 0.0066972222222222225 0"/>
      <inertia ixx="2.2378995703219564e-07" ixy="0.0" ixz="0.0" iyy="2.2378995703219564e-07" iyz="0.0" izz="2.716866376180102e-07"/>
    </inertial>
    <collision>
      <origin rpy="-1.5707963267948966 0 0" xyz="0 0.0066972222222222225 0"/>
      <geometry>
        <cylinder length="0.013394444444444445" radius="0.009611111111111112"/>
      </geometry>
    </collision>
    <visual>
      <origin rpy="-1.5707963267948966 0 0" xyz="0 0.0066972222222222225 0"/>
      <geometry>
        <cylinder length="0.013394444444444445" radius="0.009611111111111112"/>
      </geometry>
      <material name="darkgray">
        <color rgba="0.2 0.2 0.2 1"/>
      </material>
    </visual>
  </link>
  <gazebo reference="flex_joint_left_from_12_to_13">
    <implicitSpringDamper>0</implicitSpringDamper>
    <springReference>0</springReference>
    <springStiffness>0.5</springStiffness>
  </gazebo>
  <joint name="flex_joint_left_from_12_to_13" type="revolute">
    <parent link="flexible_link_left_12"/>
    <child link="flexible_link_left_13"/>
    <origin rpy="0 0 0" xyz="0 0.013394444444444445 0"/>
    <axis xyz="0 0 1"/>
    <limit effort="1000.0" lower="-1e+16" upper="1e+16" velocity="0.5"/>
    <dynamics damping="0.1" friction="0"/>
  </joint>
  <link name="flexible_link_left_12">
    <inertial>
      <mass value="0.0058823529411764705"/>
      <origin rpy="-1.5707963267948966 0 0" xyz="0 0.0066972222222222225 0"/>
      <inertia ixx="2.449727820140402e-07" ixy="0.0" ixz="0.0" iyy="2.449727820140402e-07" iyz="0.0" izz="3.140522875816993e-07"/>
    </inertial>
    <collision>
      <origin rpy="-1.5707963267948966 0 0" xyz="0 0.0066972222222222225 0"/>
      <geometry>
        <cylinder length="0.013394444444444445" radius="0.010333333333333333"/>
      </geometry>
    </collision>
    <visual>
      <origin rpy="-1.5707963267948966 0 0" xyz="0 0.0066972222222222225 0"/>
      <geometry>
        <cylinder length="0.013394444444444445" radius="0.010333333333333333"/>
      </geometry>
      <material name="darkgray">
        <color rgba="0.2 0.2 0.2 1"/>
      </material>
    </visual>
  </link>
  <gazebo reference="flex_joint_left_from_11_to_12">
    <implicitSpringDamper>0</implicitSpringDamper>
    <springReference>0</springReference>
    <springStiffness>0.5</springStiffness>
  </gazebo>
  <joint name="flex_joint_left_from_11_to_12" type="revolute">
    <parent link="flexible_link_left_11"/>
    <child link="flexible_link_left_12"/>
    <origin rpy="0 0 0" xyz="0 0.013394444444444445 0"/>
    <axis xyz="0 0 1"/>
    <limit effort="1000.0" lower="-1e+16" upper="1e+16" velocity="0.5"/>
    <dynamics damping="0.1" friction="0"/>
  </joint>
  <link name="flexible_link_left_11">
    <inertial>
      <mass value="0.0058823529411764705"/>
      <origin rpy="-1.5707963267948966 0 0" xyz="0 0.0066972222222222225 0"/>
      <inertia ixx="2.676897391672718e-07" ixy="0.0" ixz="0.0" iyy="2.676897391672718e-07" iyz="0.0" izz="3.5948620188816257e-07"/>
    </inertial>
    <collision>
      <origin rpy="-1.5707963267948966 0 0" xyz="0 0.0066972222222222225 0"/>
      <geometry>
        <cylinder length="0.013394444444444445" radius="0.011055555555555555"/>
      </geometry>
    </collision>
    <visual>
      <origin rpy="-1.5707963267948966 0 0" xyz="0 0.0066972222222222225 0"/>
      <geometry>
        <cylinder length="0.013394444444444445" radius="0.011055555555555555"/>
      </geometry>
      <material name="darkgray">
        <color rgba="0.2 0.2 0.2 1"/>
      </material>
    </visual>
  </link>
  <gazebo reference="flex_joint_left_from_10_to_11">
    <implicitSpringDamper>0</implicitSpringDamper>
    <springReference>0</springReference>
    <springStiffness>0.5</springStiffness>
  </gazebo>
  <joint name="flex_joint_left_from_10_to_11" type="revolute">
    <parent link="flexible_link_left_10"/>
    <child link="flexible_link_left_11"/>
    <origin rpy="0 0 0" xyz="0 0.013394444444444445 0"/>
    <axis xyz="0 0 1"/>
    <limit effort="1000.0" lower="-1e+16" upper="1e+16" velocity="0.5"/>
    <dynamics damping="0.1" friction="0"/>
  </joint>
  <link name="flexible_link_left_10">
    <inertial>
      <mass value="0.0058823529411764705"/>
      <origin rpy="-1.5707963267948966 0 0" xyz="0 0.0066972222222222225 0"/>
      <inertia ixx="2.919408284918906e-07" ixy="0.0" ixz="0.0" iyy="2.919408284918906e-07" iyz="0.0" izz="4.0798838053740015e-07"/>
    </inertial>
    <collision>
      <origin rpy="-1.5707963267948966 0 0" xyz="0 0.0066972222222222225 0"/>
      <geometry>
        <cylinder length="0.013394444444444445" radius="0.011777777777777778"/>
      </geometry>
    </collision>
    <visual>
      <origin rpy="-1.5707963267948966 0 0" xyz="0 0.0066972222222222225 0"/>
      <geometry>
        <cylinder length="0.013394444444444445" radius="0.011777777777777778"/>
      </geometry>
      <material name="darkgray">
        <color rgba="0.2 0.2 0.2 1"/>
      </material>
    </visual>
  </link>
  <gazebo reference="flex_joint_left_from_9_to_10">
    <implicitSpringDamper>0</implicitSpringDamper>
    <springReference>0</springReference>
    <springStiffness>0.5</springStiffness>
  </gazebo>
  <joint name="flex_joint_left_from_9_to_10" type="revolute">
    <parent link="flexible_link_left_9"/>
    <child link="flexible_link_left_10"/>
    <origin rpy="0 0 0" xyz="0 0.013394444444444445 0"/>
    <axis xyz="0 0 1"/>
    <limit effort="1000.0" lower="-1e+16" upper="1e+16" velocity="0.5"/>
    <dynamics damping="0.1" friction="0"/>
  </joint>
  <link name="flexible_link_left_9">
    <inertial>
      <mass value="0.0058823529411764705"/>
      <origin rpy="-1.5707963267948966 0 0" xyz="0 0.0066972222222222225 0"/>
      <inertia ixx="3.177260499878964e-07" ixy="0.0" ixz="0.0" iyy="3.177260499878964e-07" iyz="0.0" izz="4.5955882352941183e-07"/>
    </inertial>
    <collision>
      <origin rpy="-1.5707963267948966 0 0" xyz="0 0.0066972222222222225 0"/>
      <geometry>
        <cylinder length="0.013394444444444445" radius="0.0125"/>
      </geometry>
    </collision>
    <visual>
      <origin rpy="-1.5707963267948966 0 0" xyz="0 0.0066972222222222225 0"/>
      <geometry>
        <cylinder length="0.013394444444444445" radius="0.0125"/>
      </geometry>
      <material name="darkgray">
        <color rgba="0.2 0.2 0.2 1"/>
      </material>
    </visual>
  </link>
  <gazebo reference="flex_joint_left_from_8_to_9">
    <implicitSpringDamper>0</implicitSpringDamper>
    <springReference>0</springReference>
    <springStiffness>0.5</springStiffness>
  </gazebo>
  <joint name="flex_joint_left_from_8_to_9" type="revolute">
    <parent link="flexible_link_left_8"/>
    <child link="flexible_link_left_9"/>
    <origin rpy="0 0 0" xyz="0 0.013394444444444445 0"/>
    <axis xyz="0 0 1"/>
    <limit effort="1000.0" lower="-1e+16" upper="1e+16" velocity="0.5"/>
    <dynamics damping="0.1" friction="0"/>
  </joint>
  <link name="flexible_link_left_8">
    <inertial>
      <mass value="0.0058823529411764705"/>
      <origin rpy="-1.5707963267948966 0 0" xyz="0 0.0066972222222222225 0"/>
      <inertia ixx="3.450454036552893e-07" ixy="0.0" ixz="0.0" iyy="3.450454036552893e-07" iyz="0.0" izz="5.141975308641976e-07"/>
    </inertial>
    <collision>
      <origin rpy="-1.5707963267948966 0 0" xyz="0 0.0066972222222222225 0"/>
      <geometry>
        <cylinder length="0.013394444444444445" radius="0.013222222222222222"/>
      </geometry>
    </collision>
    <visual>
      <origin rpy="-1.5707963267948966 0 0" xyz="0 0.0066972222222222225 0"/>
      <geometry>
        <cylinder length="0.013394444444444445" radius="0.013222222222222222"/>
      </geometry>
      <material name="darkgray">
        <color rgba="0.2 0.2 0.2 1"/>
      </material>
    </visual>
  </link>
  <gazebo reference="flex_joint_left_from_7_to_8">
    <implicitSpringDamper>0</implicitSpringDamper>
    <springReference>0</springReference>
    <springStiffness>0.5</springStiffness>
  </gazebo>
  <joint name="flex_joint_left_from_7_to_8" type="revolute">
    <parent link="flexible_link_left_7"/>
    <child link="flexible_link_left_8"/>
    <origin rpy="0 0 0" xyz="0 0.013394444444444445 0"/>
    <axis xyz="0 0 1"/>
    <limit effort="1000.0" lower="-1e+16" upper="1e+16" velocity="0.5"/>
    <dynamics damping="0.1" friction="0"/>
  </joint>
  <link name="flexible_link_left_7">
    <inertial>
      <mass value="0.0058823529411764705"/>
      <origin rpy="-1.5707963267948966 0 0" xyz="0 0.0066972222222222225 0"/>
      <inertia ixx="3.7389888949406916e-07" ixy="0.0" ixz="0.0" iyy="3.7389888949406916e-07" iyz="0.0" izz="5.719045025417573e-07"/>
    </inertial>
    <collision>
      <origin rpy="-1.5707963267948966 0 0" xyz="0 0.0066972222222222225 0"/>
      <geometry>
        <cylinder length="0.013394444444444445" radius="0.013944444444444443"/>
      </geometry>
    </collision>
    <visual>
      <origin rpy="-1.5707963267948966 0 0" xyz="0 0.0066972222222222225 0"/>
      <geometry>
        <cylinder length="0.013394444444444445" radius="0.013944444444444443"/>
      </geometry>
      <material name="darkgray">
        <color rgba="0.2 0.2 0.2 1"/>
      </material>
    </visual>
  </link>
  <gazebo reference="flex_joint_left_from_6_to_7">
    <implicitSpringDamper>0</implicitSpringDamper>
    <springReference>0</springReference>
    <springStiffness>0.5</springStiffness>
  </gazebo>
  <joint name="flex_joint_left_from_6_to_7" type="revolute">
    <parent link="flexible_link_left_6"/>
    <child link="flexible_link_left_7"/>
    <origin rpy="0 0 0" xyz="0 0.013394444444444445 0"/>
    <axis xyz="0 0 1"/>
    <limit effort="1000.0" lower="-1e+16" upper="1e+16" velocity="0.5"/>
    <dynamics damping="0.1" friction="0"/>
  </joint>
  <link name="flexible_link_left_6">
    <inertial>
      <mass value="0.0058823529411764705"/>
      <origin rpy="-1.5707963267948966 0 0" xyz="0 0.0066972222222222225 0"/>
      <inertia ixx="4.0428650750423624e-07" ixy="0.0" ixz="0.0" iyy="4.0428650750423624e-07" iyz="0.0" izz="6.326797385620915e-07"/>
    </inertial>
    <collision>
      <origin rpy="-1.5707963267948966 0 0" xyz="0 0.0066972222222222225 0"/>
      <geometry>
        <cylinder length="0.013394444444444445" radius="0.014666666666666666"/>
      </geometry>
    </collision>
    <visual>
      <origin rpy="-1.5707963267948966 0 0" xyz="0 0.0066972222222222225 0"/>
      <geometry>
        <cylinder length="0.013394444444444445" radius="0.014666666666666666"/>
      </geometry>
      <material name="darkgray">
        <color rgba="0.2 0.2 0.2 1"/>
      </material>
    </visual>
  </link>
  <gazebo reference="flex_joint_left_from_5_to_6">
    <implicitSpringDamper>0</implicitSpringDamper>
    <springReference>0</springReference>
    <springStiffness>0.5</springStiffness>
  </gazebo>
  <joint name="flex_joint_left_from_5_to_6" type="revolute">
    <parent link="flexible_link_left_5"/>
    <child link="flexible_link_left_6"/>
    <origin rpy="0 0 0" xyz="0 0.013394444444444445 0"/>
    <axis xyz="0 0 1"/>
    <limit effort="1000.0" lower="-1e+16" upper="1e+16" velocity="0.5"/>
    <dynamics damping="0.1" friction="0"/>
  </joint>
  <link name="flexible_link_left_5">
    <inertial>
      <mass value="0.0058823529411764705"/>
      <origin rpy="-1.5707963267948966 0 0" xyz="0 0.0066972222222222225 0"/>
      <inertia ixx="4.362082576857904e-07" ixy="0.0" ixz="0.0" iyy="4.362082576857904e-07" iyz="0.0" izz="6.965232389251998e-07"/>
    </inertial>
    <collision>
      <origin rpy="-1.5707963267948966 0 0" xyz="0 0.0066972222222222225 0"/>
      <geometry>
        <cylinder length="0.013394444444444445" radius="0.01538888888888889"/>
      </geometry>
    </collision>
    <visual>
      <origin rpy="-1.5707963267948966 0 0" xyz="0 0.0066972222222222225 0"/>
      <geometry>
        <cylinder length="0.013394444444444445" radius="0.01538888888888889"/>
      </geometry>
      <material name="darkgray">
        <color rgba="0.2 0.2 0.2 1"/>
      </material>
    </visual>
  </link>
  <gazebo reference="flex_joint_left_from_4_to_5">
    <implicitSpringDamper>0</implicitSpringDamper>
    <springReference>0</springReference>
    <springStiffness>0.5</springStiffness>
  </gazebo>
  <joint name="flex_joint_left_from_4_to_5" type="revolute">
    <parent link="flexible_link_left_4"/>
    <child link="flexible_link_left_5"/>
    <origin rpy="0 0 0" xyz="0 0.013394444444444445 0"/>
    <axis xyz="0 0 1"/>
    <limit effort="1000.0" lower="-1e+16" upper="1e+16" velocity="0.5"/>
    <dynamics damping="0.1" friction="0"/>
  </joint>
  <link name="flexible_link_left_4">
    <inertial>
      <mass value="0.0058823529411764705"/>
      <origin rpy="-1.5707963267948966 0 0" xyz="0 0.0066972222222222225 0"/>
      <inertia ixx="4.696641400387315e-07" ixy="0.0" ixz="0.0" iyy="4.696641400387315e-07" iyz="0.0" izz="7.63435003631082e-07"/>
    </inertial>
    <collision>
      <origin rpy="-1.5707963267948966 0 0" xyz="0 0.0066972222222222225 0"/>
      <geometry>
        <cylinder length="0.013394444444444445" radius="0.01611111111111111"/>
      </geometry>
    </collision>
    <visual>
      <origin rpy="-1.5707963267948966 0 0" xyz="0 0.0066972222222222225 0"/>
      <geometry>
        <cylinder length="0.013394444444444445" radius="0.01611111111111111"/>
      </geometry>
      <material name="darkgray">
        <color rgba="0.2 0.2 0.2 1"/>
      </material>
    </visual>
  </link>
  <gazebo reference="flex_joint_left_from_3_to_4">
    <implicitSpringDamper>0</implicitSpringDamper>
    <springReference>0</springReference>
    <springStiffness>0.5</springStiffness>
  </gazebo>
  <joint name="flex_joint_left_from_3_to_4" type="revolute">
    <parent link="flexible_link_left_3"/>
    <child link="flexible_link_left_4"/>
    <origin rpy="0 0 0" xyz="0 0.013394444444444445 0"/>
    <axis xyz="0 0 1"/>
    <limit effort="1000.0" lower="-1e+16" upper="1e+16" velocity="0.5"/>
    <dynamics damping="0.1" friction="0"/>
  </joint>
  <link name="flexible_link_left_3">
    <inertial>
      <mass value="0.0058823529411764705"/>
      <origin rpy="-1.5707963267948966 0 0" xyz="0 0.0066972222222222225 0"/>
      <inertia ixx="5.046541545630597e-07" ixy="0.0" ixz="0.0" iyy="5.046541545630597e-07" iyz="0.0" izz="8.334150326797384e-07"/>
    </inertial>
    <collision>
      <origin rpy="-1.5707963267948966 0 0" xyz="0 0.0066972222222222225 0"/>
      <geometry>
        <cylinder length="0.013394444444444445" radius="0.016833333333333332"/>
      </geometry>
    </collision>
    <visual>
      <origin rpy="-1.5707963267948966 0 0" xyz="0 0.0066972222222222225 0"/>
      <geometry>
        <cylinder length="0.013394444444444445" radius="0.016833333333333332"/>
      </geometry>
      <material name="darkgray">
        <color rgba="0.2 0.2 0.2 1"/>
      </material>
    </visual>
  </link>
  <gazebo reference="flex_joint_left_from_2_to_3">
    <implicitSpringDamper>0</implicitSpringDamper>
    <springReference>0</springReference>
    <springStiffness>0.5</springStiffness>
  </gazebo>
  <joint name="flex_joint_left_from_2_to_3" type="revolute">
    <parent link="flexible_link_left_2"/>
    <child link="flexible_link_left_3"/>
    <origin rpy="0 0 0" xyz="0 0.013394444444444445 0"/>
    <axis xyz="0 0 1"/>
    <limit effort="1000.0" lower="-1e+16" upper="1e+16" velocity="0.5"/>
    <dynamics damping="0.1" friction="0"/>
  </joint>
  <link name="flexible_link_left_2">
    <inertial>
      <mass value="0.0058823529411764705"/>
      <origin rpy="-1.5707963267948966 0 0" xyz="0 0.0066972222222222225 0"/>
      <inertia ixx="5.41178301258775e-07" ixy="0.0" ixz="0.0" iyy="5.41178301258775e-07" iyz="0.0" izz="9.06463326071169e-07"/>
    </inertial>
    <collision>
      <origin rpy="-1.5707963267948966 0 0" xyz="0 0.0066972222222222225 0"/>
      <geometry>
        <cylinder length="0.013394444444444445" radius="0.017555555555555553"/>
      </geometry>
    </collision>
    <visual>
      <origin rpy="-1.5707963267948966 0 0" xyz="0 0.0066972222222222225 0"/>
      <geometry>
        <cylinder length="0.013394444444444445" radius="0.017555555555555553"/>
      </geometry>
      <material name="darkgray">
        <color rgba="0.2 0.2 0.2 1"/>
      </material>
    </visual>
  </link>
  <gazebo reference="flex_joint_left_from_1_to_2">
    <implicitSpringDamper>0</implicitSpringDamper>
    <springReference>0</springReference>
    <springStiffness>0.5</springStiffness>
  </gazebo>
  <joint name="flex_joint_left_from_1_to_2" type="revolute">
    <parent link="flexible_link_left_1"/>
    <child link="flexible_link_left_2"/>
    <origin rpy="0 0 0" xyz="0 0.013394444444444445 0"/>
    <axis xyz="0 0 1"/>
    <limit effort="1000.0" lower="-1e+16" upper="1e+16" velocity="0.5"/>
    <dynamics damping="0.1" friction="0"/>
  </joint>
  <joint name="FixJoint_Left" type="revolute">
    <parent link="rod_link_left"/>
    <origin rpy="-1.5708 0 0" xyz="0 0 -0.35"/>
    <child link="flexible_link_left_1"/>
    <axis xyz="0 0 1"/>
    <limit effort="10" lower="0.0" upper="0.0" velocity="1"/>
  </joint>
  <joint name="FixJoint_Right" type="revolute">
    <parent link="rod_link_right"/>
    <origin rpy="-1.5708 0 0" xyz="0 0 -0.35"/>
    <child link="flexible_link_right_1"/>
    <axis xyz="0 0 1"/>
    <limit effort="10" lower="0.0" upper="0.0" velocity="1"/>
  </joint>
  <gazebo>
    <plugin filename="gz-sim-joint-controller-system" name="gz::sim::systems::JointController">
      <joint_name>servo_move_right</joint_name>
      <initial_velocity>0.0</initial_velocity>
      <topic>joint_right_vel</topic>
    </plugin>
    <plugin filename="gz-sim-joint-controller-system" name="gz::sim::systems::JointController">
      <joint_name>servo_move_left</joint_name>
      <initial_velocity>0.0</initial_velocity>
      <topic>joint_left_vel</topic>
    </plugin>
    <plugin filename="SoftFinger" name="gz::sim::systems::SoftFinger">
      <joint_name>flex_joint_right_from_1_to_2</joint_name>
      <joint_name>flex_joint_right_from_2_to_3</joint_name>
      <joint_name>flex_joint_right_from_3_to_4</joint_name>
      <joint_name>flex_joint_right_from_4_to_5</joint_name>
      <joint_name>flex_joint_right_from_5_to_6</joint_name>
      <joint_name>flex_joint_right_from_6_to_7</joint_name>
      <joint_name>flex_joint_right_from_7_to_8</joint_name>
      <joint_name>flex_joint_right_from_8_to_9</joint_name>
      <joint_name>flex_joint_right_from_9_to_10</joint_name>
      <joint_name>flex_joint_right_from_10_to_11</joint_name>
      <joint_name>flex_joint_right_from_11_to_12</joint_name>
      <joint_name>flex_joint_right_from_12_to_13</joint_name>
      <joint_name>flex_joint_right_from_13_to_14</joint_name>
      <joint_name>flex_joint_right_from_14_to_15</joint_name>
      <joint_name>flex_joint_right_from_15_to_16</joint_name>
      <joint_name>flex_joint_right_from_16_to_17</joint_name>
      <joint_name>flex_joint_right_from_17_to_18</joint_name>
      <topic>bend_r</topic>
      <steps>18</steps>
    </plugin>
    <plugin filename="SoftFinger" name="gz::sim::systems::SoftFinger">
      <joint_name>flex_joint_left_from_1_to_2</joint_name>
      <joint_name>flex_joint_left_from_2_to_3</joint_name>
      <joint_name>flex_joint_left_from_3_to_4</joint_name>
      <joint_name>flex_joint_left_from_4_to_5</joint_name>
      <joint_name>flex_joint_left_from_5_to_6</joint_name>
      <joint_name>flex_joint_left_from_6_to_7</joint_name>
      <joint_name>flex_joint_left_from_7_to_8</joint_name>
      <joint_name>flex_joint_left_from_8_to_9</joint_name>
      <joint_name>flex_joint_left_from_9_to_10</joint_name>
      <joint_name>flex_joint_left_from_10_to_11</joint_name>
      <joint_name>flex_joint_left_from_11_to_12</joint_name>
      <joint_name>flex_joint_left_from_12_to_13</joint_name>
      <joint_name>flex_joint_left_from_13_to_14</joint_name>
      <joint_name>flex_joint_left_from_14_to_15</joint_name>
      <joint_name>flex_joint_left_from_15_to_16</joint_name>
      <joint_name>flex_joint_left_from_16_to_17</joint_name>
      <joint_name>flex_joint_left_from_17_to_18</joint_name>
      <topic>bend_l</topic>
      <steps>18</steps>
    </plugin>
  </gazebo>
  <link name="base_link">
    <collision>
      <origin rpy="0 0 0" xyz="0 0 0"/>
      <geometry>
        <box size="0.2 0.2 0.05"/>
      </geometry>
    </collision>
    <visual>
      <origin rpy="0 0 0" xyz="0 0 0"/>
      <geometry>
        <mesh filename="meshes\Holybro_No_Legs.dae"/>
      </geometry>
      <material name="darkgray">
        <color rgba="0.2 0.2 0.2 1"/>
      </material>
    </visual>
    <inertial>
      <mass value="2.0"/>
      <inertia ixx="0.0208" ixy="0.0" ixz="0.0" iyy="0.0208" iyz="0.0" izz="0.0408"/>
    </inertial>
  </link>
  <link name="fixed_base">
    <inertial>
      <origin rpy="0 0 0" xyz="0 0 -0.060875"/>
      <mass value="0.2"/>
      <inertia ixx="0.00090045" ixy="0" ixz="0" iyy="0.000302155" iyz="0" izz="0.0007085"/>
    </inertial>
    <collision>
      <origin rpy="0 0 0" xyz="0 0 -0.060875"/>
      <geometry>
        <box size="0.1175 0.198 0.12175"/>
      </geometry>
    </collision>
    <visual>
      <geometry>
        <mesh filename="meshes\DroneArmsBase.stl"/>
      </geometry>
      <material name="darkgray">
        <color rgba="0.2 0.2 0.8 1"/>
      </material>
    </visual>
  </link>
  <joint name="fix_arms_to_drone" type="revolute">
    <parent link="base_link"/>
    <origin rpy="0 0 3.1416" xyz="0 0 -0.016"/>
    <child link="fixed_base"/>
    <limit effort="100" lower="0" upper="0" velocity="1"/>
  </joint>
  <gazebo reference="base_link">
    <sensor name="air_pressure_sensor" type="air_pressure">
      <always_on>1</always_on>
      <update_rate>50</update_rate>
      <air_pressure>
        <pressure>
          <noise type="gaussian">
            <mean>0</mean>
            <stddev>0.01</stddev>
          </noise>
        </pressure>
      </air_pressure>
    </sensor>
    <sensor name="imu_sensor" type="imu">
      <always_on>1</always_on>
      <update_rate>1000</update_rate>
      <imu>
        <angular_velocity>
          <x>
            <noise type="gaussian">
              <mean>0</mean>
              <stddev>0.0001</stddev>
              <dynamic_bias_stddev>0</dynamic_bias_stddev>
              <dynamic_bias_correlation_time>1000</dynamic_bias_correlation_time>
            </noise>
          </x>
          <y>
            <noise type="gaussian">
              <mean>0</mean>
              <stddev>0.0001</stddev>
              <dynamic_bias_stddev>0</dynamic_bias_stddev>
              <dynamic_bias_correlation_time>1000</dynamic_bias_correlation_time>
            </noise>
          </y>
          <z>
            <noise type="gaussian">
              <mean>0</mean>
              <stddev>0.0001</stddev>
              <dynamic_bias_stddev>0</dynamic_bias_stddev>
              <dynamic_bias_correlation_time>1000</dynamic_bias_correlation_time>
            </noise>
          </z>
        </angular_velocity>
        <linear_acceleration>
          <x>
            <noise type="gaussian">
              <mean>0</mean>
              <stddev>0.0001</stddev>
              <dynamic_bias_stddev>0</dynamic_bias_stddev>
              <dynamic_bias_correlation_time>300</dynamic_bias_correlation_time>
            </noise>
          </x>
          <y>
            <noise type="gaussian">
              <mean>0</mean>
              <stddev>0.0001</stddev>
              <dynamic_bias_stddev>0</dynamic_bias_stddev>
              <dynamic_bias_correlation_time>300</dynamic_bias_correlation_time>
            </noise>
          </y>
          <z>
            <noise type="gaussian">
              <mean>0</mean>
              <stddev>0.0001</stddev>
              <dynamic_bias_stddev>0</dynamic_bias_stddev>
              <dynamic_bias_correlation_time>300</dynamic_bias_correlation_time>
            </noise>
          </z>
        </linear_acceleration>
      </imu>
    </sensor>
    <sensor name="navsat_sensor" type="navsat">
      <always_on>1</always_on>
      <update_rate>100</update_rate>
    </sensor>
  </gazebo>
  <gazebo>
    <link name="rotor_0">
      <gravity>true</gravity>
      <self_collide>false</self_collide>
      <velocity_decay/>
      <pose>0.175 -0.175 0.03 0 0 0</pose>
      <inertial>
        <mass>0.016076923076923075</mass>
        <inertia>
          <ixx>3.8464910483993325e-07</ixx>
          <iyy>2.6115851691700804e-05</iyy>
          <izz>2.649858234714004e-05</izz>
        </inertia>
      </inertial>
      <visual name="rotor_0_visual">
        <pose>0 0 0 0 0 0</pose>
        <geometry>
          <mesh>
            <scale>0.72 0.72 0.8461538461538461</scale>
            <uri>meshes\centered_prop_ccw.stl</uri>
          </mesh>
        </geometry>
        <material>
          <script>
            <name>Gazebo/Blue</name>
            <uri>file://media/materials/scripts/gazebo.material</uri>
          </script>
        </material>
      </visual>
      <collision name="rotor_0_collision">
        <pose>0 0 0 0 0 0 </pose>
        <geometry>
          <box>
            <size>0.2792307692307692 0.016923076923076923 0.0008461538461538462</size>
          </box>
        </geometry>
        <surface>
          <contact>
            <ode>
              <min_depth>0.001</min_depth>
              <max_vel>0</max_vel>
            </ode>
          </contact>
          <friction>
            <ode/>
          </friction>
        </surface>
      </collision>
    </link>
    <joint name="rotor_0_joint" type="revolute">
      <parent>base_link</parent>
      <child>rotor_0</child>
      <axis>
        <xyz>0 0 1</xyz>
        <limit>
          <lower>-1e+16</lower>
          <upper>1e+16</upper>
        </limit>
        <dynamics>
          <spring_reference>0</spring_reference>
          <spring_stiffness>0</spring_stiffness>
        </dynamics>
      </axis>
    </joint>
    <plugin filename="gz-sim-multicopter-motor-model-system" name="gz::sim::systems::MulticopterMotorModel">
      <jointName>rotor_0_joint</jointName>
      <linkName>rotor_0</linkName>
      <turningDirection>ccw</turningDirection>
      <timeConstantUp>0.0125</timeConstantUp>
      <timeConstantDown>0.025</timeConstantDown>
      <maxRotVelocity>1000.0</maxRotVelocity>
      <motorConstant>3.419432e-05</motorConstant>
      <momentConstant>0.016</momentConstant>
      <commandSubTopic>command/motor_speed</commandSubTopic>
      <motorNumber>0</motorNumber>
      <rotorDragCoefficient>8.06428e-05</rotorDragCoefficient>
      <rollingMomentCoefficient>1e-06</rollingMomentCoefficient>
      <rotorVelocitySlowdownSim>10</rotorVelocitySlowdownSim>
      <motorType>velocity</motorType>
    </plugin>
  </gazebo>
  <gazebo>
    <link name="rotor_1">
      <gravity>true</gravity>
      <self_collide>false</self_collide>
      <velocity_decay/>
      <pose>-0.175 0.175 0.03 0 0 0</pose>
      <inertial>
        <mass>0.016076923076923075</mass>
        <inertia>
          <ixx>3.8464910483993325e-07</ixx>
          <iyy>2.6115851691700804e-05</iyy>
          <izz>2.649858234714004e-05</izz>
        </inertia>
      </inertial>
      <visual name="rotor_1_visual">
        <pose>0 0 0 0 0 0</pose>
        <geometry>
          <mesh>
            <scale>0.72 0.72 0.8461538461538461</scale>
            <uri>meshes\centered_prop_ccw.stl</uri>
          </mesh>
        </geometry>
        <material>
          <script>
            <name>Gazebo/Blue</name>
            <uri>file://media/materials/scripts/gazebo.material</uri>
          </script>
        </material>
      </visual>
      <collision name="rotor_1_collision">
        <pose>0 0 0 0 0 0 </pose>
        <geometry>
          <box>
            <size>0.2792307692307692 0.016923076923076923 0.0008461538461538462</size>
          </box>
        </geometry>
        <surface>
          <contact>
            <ode>
              <min_depth>0.001</min_depth>
              <max_vel>0</max_vel>
            </ode>
          </contact>
          <friction>
            <ode/>
          </friction>
        </surface>
      </collision>
    </link>
    <joint name="rotor_1_joint" type="revolute">
      <parent>base_link</parent>
      <child>rotor_1</child>
      <axis>
        <xyz>0 0 1</xyz>
        <limit>
          <lower>-1e+16</lower>
          <upper>1e+16</upper>
        </limit>
        <dynamics>
          <spring_reference>0</spring_reference>
          <spring_stiffness>0</spring_stiffness>
        </dynamics>
      </axis>
    </joint>
    <plugin filename="gz-sim-multicopter-motor-model-system" name="gz::sim::systems::MulticopterMotorModel">
      <jointName>rotor_1_joint</jointName>
      <linkName>rotor_1</linkName>
      <turningDirection>ccw</turningDirection>
      <timeConstantUp>0.0125</timeConstantUp>
      <timeConstantDown>0.025</timeConstantDown>
      <maxRotVelocity>1000.0</maxRotVelocity>
      <motorConstant>3.419432e-05</motorConstant>
      <momentConstant>0.016</momentConstant>
      <commandSubTopic>command/motor_speed</commandSubTopic>
      <motorNumber>1</motorNumber>
      <rotorDragCoefficient>8.06428e-05</rotorDragCoefficient>
      <rollingMomentCoefficient>1e-06</rollingMomentCoefficient>
      <rotorVelocitySlowdownSim>10</rotorVelocitySlowdownSim>
      <motorType>velocity</motorType>
    </plugin>
  </gazebo>
  <gazebo>
    <link name="rotor_2">
      <gravity>true</gravity>
      <self_collide>false</self_collide>
      <velocity_decay/>
      <pose>0.175 0.175 0.03 0 0 0</pose>
      <inertial>
        <mass>0.016076923076923075</mass>
        <inertia>
          <ixx>3.8464910483993325e-07</ixx>
          <iyy>2.6115851691700804e-05</iyy>
          <izz>2.649858234714004e-05</izz>
        </inertia>
      </inertial>
      <visual name="rotor_2_visual">
        <pose>0 0 0 0 0 0</pose>
        <geometry>
          <mesh>
            <scale>0.72 0.72 0.8461538461538461</scale>
            <uri>meshes\centered_prop_ccw.stl</uri>
          </mesh>
        </geometry>
        <material>
          <script>
            <name>Gazebo/Red</name>
            <uri>file://media/materials/scripts/gazebo.material</uri>
          </script>
        </material>
      </visual>
      <collision name="rotor_2_collision">
        <pose>0 0 0 0 0 0 </pose>
        <geometry>
          <box>
            <size>0.2792307692307692 0.016923076923076923 0.0008461538461538462</size>
          </box>
        </geometry>
        <surface>
          <contact>
            <ode>
              <min_depth>0.001</min_depth>
              <max_vel>0</max_vel>
            </ode>
          </contact>
          <friction>
            <ode/>
          </friction>
        </surface>
      </collision>
    </link>
    <joint name="rotor_2_joint" type="revolute">
      <parent>base_link</parent>
      <child>rotor_2</child>
      <axis>
        <xyz>0 0 1</xyz>
        <limit>
          <lower>-1e+16</lower>
          <upper>1e+16</upper>
        </limit>
        <dynamics>
          <spring_reference>0</spring_reference>
          <spring_stiffness>0</spring_stiffness>
        </dynamics>
      </axis>
    </joint>
    <plugin filename="gz-sim-multicopter-motor-model-system" name="gz::sim::systems::MulticopterMotorModel">
      <jointName>rotor_2_joint</jointName>
      <linkName>rotor_2</linkName>
      <turningDirection>cw</turningDirection>
      <timeConstantUp>0.0125</timeConstantUp>
      <timeConstantDown>0.025</timeConstantDown>
      <maxRotVelocity>1000.0</maxRotVelocity>
      <motorConstant>3.419432e-05</motorConstant>
      <momentConstant>0.016</momentConstant>
      <commandSubTopic>command/motor_speed</commandSubTopic>
      <motorNumber>2</motorNumber>
      <rotorDragCoefficient>8.06428e-05</rotorDragCoefficient>
      <rollingMomentCoefficient>1e-06</rollingMomentCoefficient>
      <rotorVelocitySlowdownSim>10</rotorVelocitySlowdownSim>
      <motorType>velocity</motorType>
    </plugin>
  </gazebo>
  <gazebo>
    <link name="rotor_3">
      <gravity>true</gravity>
      <self_collide>false</self_collide>
      <velocity_decay/>
      <pose>-0.175 -0.175 0.03 0 0 0</pose>
      <inertial>
        <mass>0.016076923076923075</mass>
        <inertia>
          <ixx>3.8464910483993325e-07</ixx>
          <iyy>2.6115851691700804e-05</iyy>
          <izz>2.649858234714004e-05</izz>
        </inertia>
      </inertial>
      <visual name="rotor_3_visual">
        <pose>0 0 0 0 0 0</pose>
        <geometry>
          <mesh>
            <scale>0.72 0.72 0.8461538461538461</scale>
            <uri>meshes\centered_prop_ccw.stl</uri>
          </mesh>
        </geometry>
        <material>
          <script>
            <name>Gazebo/Red</name>
            <uri>file://media/materials/scripts/gazebo.material</uri>
          </script>
        </material>
      </visual>
      <collision name="rotor_3_collision">
        <pose>0 0 0 0 0 0 </pose>
        <geometry>
          <box>
            <size>0.2792307692307692 0.016923076923076923 0.0008461538461538462</size>
          </box>
        </geometry>
        <surface>
          <contact>
            <ode>
              <min_depth>0.001</min_depth>
              <max_vel>0</max_vel>
            </ode>
          </contact>
          <friction>
            <ode/>
          </friction>
        </surface>
      </collision>
    </link>
    <joint name="rotor_3_joint" type="revolute">
      <parent>base_link</parent>
      <child>rotor_3</child>
      <axis>
        <xyz>0 0 1</xyz>
        <limit>
          <lower>-1e+16</lower>
          <upper>1e+16</upper>
        </limit>
        <dynamics>
          <spring_reference>0</spring_reference>
          <spring_stiffness>0</spring_stiffness>
        </dynamics>
      </axis>
    </joint>
    <plugin filename="gz-sim-multicopter-motor-model-system" name="gz::sim::systems::MulticopterMotorModel">
      <jointName>rotor_3_joint</jointName>
      <linkName>rotor_3</linkName>
      <turningDirection>cw</turningDirection>
      <timeConstantUp>0.0125</timeConstantUp>
      <timeConstantDown>0.025</timeConstantDown>
      <maxRotVelocity>1000.0</maxRotVelocity>
      <motorConstant>3.419432e-05</motorConstant>
      <momentConstant>0.016</momentConstant>
      <commandSubTopic>command/motor_speed</commandSubTopic>
      <motorNumber>3</motorNumber>
      <rotorDragCoefficient>8.06428e-05</rotorDragCoefficient>
      <rollingMomentCoefficient>1e-06</rollingMomentCoefficient>
      <rotorVelocitySlowdownSim>10</rotorVelocitySlowdownSim>
      <motorType>velocity</motorType>
    </plugin>
  </gazebo>
  <gazebo>
    <plugin filename="gz-sim-odometry-publisher-system" name="gz::sim::systems::OdometryPublisher">
      <odom_frame>odom</odom_frame>
      <robot_base_frame>base_link</robot_base_frame>
      <dimensions>3</dimensions>
    </plugin>
    <plugin filename="gz-sim-joint-state-publisher-system" name="gz::sim::systems::JointStatePublisher">
      <joint_name>servo_move_right</joint_name>
      <joint_name>servo_move_left</joint_name>
    </plugin>
    <plugin filename="gz-sim-joint-state-publisher-system" name="gz::sim::systems::JointStatePublisher">
      <joint_name>servo_move_right</joint_name>
      <joint_name>servo_move_left</joint_name>
      <!-- right -->
      <joint_name>flex_joint_right_from_1_to_2</joint_name>
      <joint_name>flex_joint_right_from_2_to_3</joint_name>
      <joint_name>flex_joint_right_from_3_to_4</joint_name>
      <joint_name>flex_joint_right_from_4_to_5</joint_name>
      <joint_name>flex_joint_right_from_5_to_6</joint_name>
      <joint_name>flex_joint_right_from_6_to_7</joint_name>
      <joint_name>flex_joint_right_from_7_to_8</joint_name>
      <joint_name>flex_joint_right_from_8_to_9</joint_name>
      <joint_name>flex_joint_right_from_9_to_10</joint_name>
      <joint_name>flex_joint_right_from_10_to_11</joint_name>
      <joint_name>flex_joint_right_from_11_to_12</joint_name>
      <joint_name>flex_joint_right_from_12_to_13</joint_name>
      <joint_name>flex_joint_right_from_13_to_14</joint_name>
      <joint_name>flex_joint_right_from_14_to_15</joint_name>
      <joint_name>flex_joint_right_from_15_to_16</joint_name>
      <joint_name>flex_joint_right_from_16_to_17</joint_name>
      <joint_name>flex_joint_right_from_17_to_18</joint_name>
      <!-- left -->
      <joint_name>flex_joint_left_from_1_to_2</joint_name>
      <joint_name>flex_joint_left_from_2_to_3</joint_name>
      <joint_name>flex_joint_left_from_3_to_4</joint_name>
      <joint_name>flex_joint_left_from_4_to_5</joint_name>
      <joint_name>flex_joint_left_from_5_to_6</joint_name>
      <joint_name>flex_joint_left_from_6_to_7</joint_name>
      <joint_name>flex_joint_left_from_7_to_8</joint_name>
      <joint_name>flex_joint_left_from_8_to_9</joint_name>
      <joint_name>flex_joint_left_from_9_to_10</joint_name>
      <joint_name>flex_joint_left_from_10_to_11</joint_name>
      <joint_name>flex_joint_left_from_11_to_12</joint_name>
      <joint_name>flex_joint_left_from_12_to_13</joint_name>
      <joint_name>flex_joint_left_from_13_to_14</joint_name>
      <joint_name>flex_joint_left_from_14_to_15</joint_name>
      <joint_name>flex_joint_left_from_15_to_16</joint_name>
      <joint_name>flex_joint_left_from_16_to_17</joint_name>
      <joint_name>flex_joint_left_from_17_to_18</joint_name>
      <topic>/complete_joint_states</topic>
      <joint_state_publisher_name>complete_joint_state_publisher</joint_state_publisher_name>
    </plugin>
    <plugin filename="MocapPub" name="gz::sim::systems::MocapPub">
    </plugin>
  </gazebo>
</robot>
